Workbook

Sheet Clientwise Comparison
C1: NS Debit | D1: Tally Debit | E1: Is Matched | F1: Reason | G1: NS Credit | H1: Tally Credit | I1: Is Matched | J1: Reason | K1: NC Closing | L1: Tally Closing
A2: Accenture Solutions Pvt Ltd | B2: SB21386 | C2: =VLOOKUP(B2,'NS Balance'!D:F,3,FALSE) -> 394474 | D2: =VLOOKUP(B2,'Tally Balance'!A:C,3,FALSE) -> 394474 | E2: =C2=D2 -> TRUE | G2: =VLOOKUP(B2,'NS Balance'!D:G,4,FALSE) -> 0 | H2: =VLOOKUP(B2,'Tally Balance'!A:D,4,FALSE) -> 0 | I2: =G2=H2 -> TRUE | L2: =VLOOKUP(B2,'Tally Balance'!A:E,5,FALSE) -> 394474
A3: Accenture Solutions Pvt Ltd | B3: SB22376 | C3: =VLOOKUP(B3,'NS Balance'!D:F,3,FALSE) -> 326914 | D3: =VLOOKUP(B3,'Tally Balance'!A:C,3,FALSE) -> 326914 | E3: =C3=D3 -> TRUE | G3: =VLOOKUP(B3,'NS Balance'!D:G,4,FALSE) -> 309507 | H3: =VLOOKUP(B3,'Tally Balance'!A:D,4,FALSE) -> 309507 | I3: =G3=H3 -> TRUE | L3: =VLOOKUP(B3,'Tally Balance'!A:E,5,FALSE) -> 17407
A4: Accenture Solutions Pvt Ltd | B4: SB22511 | C4: =VLOOKUP(B4,'NS Balance'!D:F,3,FALSE) -> 1800000 | D4: =VLOOKUP(B4,'Tally Balance'!A:C,3,FALSE) -> 1800000 | E4: =C4=D4 -> TRUE | G4: =VLOOKUP(B4,'NS Balance'!D:G,4,FALSE) -> 2400000 | H4: =VLOOKUP(B4,'Tally Balance'!A:D,4,FALSE) -> 2400000 | I4: =G4=H4 -> TRUE | L4: =VLOOKUP(B4,'Tally Balance'!A:E,5,FALSE) -> 600000
A5: Accenture Solutions Pvt Ltd | B5: SB22526 | C5: =VLOOKUP(B5,'NS Balance'!D:F,3,FALSE) -> 115008 | D5: =VLOOKUP(B5,'Tally Balance'!A:C,3,FALSE) -> 115008 | E5: =C5=D5 -> TRUE | G5: =VLOOKUP(B5,'NS Balance'!D:G,4,FALSE) -> 121792 | H5: =VLOOKUP(B5,'Tally Balance'!A:D,4,FALSE) -> 121792 | I5: =G5=H5 -> TRUE | L5: =VLOOKUP(B5,'Tally Balance'!A:E,5,FALSE) -> 6784
A6: Accenture Solutions Pvt Ltd | B6: SB22570 | C6: =VLOOKUP(B6,'NS Balance'!D:F,3,FALSE) -> 94380 | D6: =VLOOKUP(B6,'Tally Balance'!A:C,3,FALSE) -> 94380 | E6: =C6=D6 -> TRUE | G6: =VLOOKUP(B6,'NS Balance'!D:G,4,FALSE) -> 171050 | H6: =VLOOKUP(B6,'Tally Balance'!A:D,4,FALSE) -> 171050 | I6: =G6=H6 -> TRUE | L6: =VLOOKUP(B6,'Tally Balance'!A:E,5,FALSE) -> 76670
A7: Accenture Solutions Pvt Ltd | B7: SB22600 | C7: =VLOOKUP(B7,'NS Balance'!D:F,3,FALSE) -> 149700 | D7: =VLOOKUP(B7,'Tally Balance'!A:C,3,FALSE) -> 149700 | E7: =C7=D7 -> TRUE | G7: =VLOOKUP(B7,'NS Balance'!D:G,4,FALSE) -> 192016 | H7: =VLOOKUP(B7,'Tally Balance'!A:D,4,FALSE) -> 192016 | I7: =G7=H7 -> TRUE | L7: =VLOOKUP(B7,'Tally Balance'!A:E,5,FALSE) -> 42316
A8: Accenture Solutions Pvt Ltd | B8: SB22632 | C8: =VLOOKUP(B8,'NS Balance'!D:F,3,FALSE) -> 431402 | D8: =VLOOKUP(B8,'Tally Balance'!A:C,3,FALSE) -> 431402 | E8: =C8=D8 -> TRUE | G8: =VLOOKUP(B8,'NS Balance'!D:G,4,FALSE) -> 553080 | H8: =VLOOKUP(B8,'Tally Balance'!A:D,4,FALSE) -> 553080 | I8: =G8=H8 -> TRUE | L8: =VLOOKUP(B8,'Tally Balance'!A:E,5,FALSE) -> 121678
A9: Clarivate Analytics India Pvt Ltd | B9: SB22581 | C9: =VLOOKUP(B9,'NS Balance'!D:F,3,FALSE) -> 511290 | D9: =VLOOKUP(B9,'Tally Balance'!A:C,3,FALSE) -> 511290 | E9: =C9=D9 -> TRUE | G9: =VLOOKUP(B9,'NS Balance'!D:G,4,FALSE) -> 771075 | H9: =VLOOKUP(B9,'Tally Balance'!A:D,4,FALSE) -> 771075 | I9: =G9=H9 -> TRUE | L9: =VLOOKUP(B9,'Tally Balance'!A:E,5,FALSE) -> 259785
A10: Indian Explosives Pvt Ltd | B10: SB22347 | C10: =VLOOKUP(B10,'NS Balance'!D:F,3,FALSE) -> 83600 | D10: =VLOOKUP(B10,'Tally Balance'!A:C,3,FALSE) -> 83600 | E10: =C10=D10 -> TRUE | G10: =VLOOKUP(B10,'NS Balance'!D:G,4,FALSE) -> 83600 | H10: =VLOOKUP(B10,'Tally Balance'!A:D,4,FALSE) -> 83600 | I10: =G10=H10 -> TRUE | L10: =VLOOKUP(B10,'Tally Balance'!A:E,5,FALSE) -> 0
A11: NTT DATA Business Solutions Pvt Ltd | B11: SB22384 | C11: =VLOOKUP(B11,'NS Balance'!D:F,3,FALSE) -> 727580 | D11: =VLOOKUP(B11,'Tally Balance'!A:C,3,FALSE) -> 727110 | E11: =C11=D11 -> FALSE | F11: A/2025/PB Exe/0891 - 470.0 in NS | G11: =VLOOKUP(B11,'NS Balance'!D:G,4,FALSE) -> 1226174 | H11: =VLOOKUP(B11,'Tally Balance'!A:D,4,FALSE) -> 1155224 | I11: =G11=H11 -> FALSE | J11: Difference of 70950 | L11: =VLOOKUP(B11,'Tally Balance'!A:E,5,FALSE) -> 428114
A12: SAP India Pvt Ltd | B12: SB22124 | C12: =VLOOKUP(B12,'NS Balance'!D:F,3,FALSE) -> 1545455 | D12: =VLOOKUP(B12,'Tally Balance'!A:C,3,FALSE) -> 1545455 | E12: =C12=D12 -> TRUE | G12: =VLOOKUP(B12,'NS Balance'!D:G,4,FALSE) -> 1545455 | H12: =VLOOKUP(B12,'Tally Balance'!A:D,4,FALSE) -> 1545455 | I12: =G12=H12 -> TRUE | L12: =VLOOKUP(B12,'Tally Balance'!A:E,5,FALSE) -> 0
A13: SAP India Pvt Ltd | B13: SB22428 | C13: =VLOOKUP(B13,'NS Balance'!D:F,3,FALSE) -> 5842385.1 | D13: =VLOOKUP(B13,'Tally Balance'!A:C,3,FALSE) -> 5842385.1 | E13: =C13=D13 -> TRUE | G13: =VLOOKUP(B13,'NS Balance'!D:G,4,FALSE) -> 5842385.1 | H13: =VLOOKUP(B13,'Tally Balance'!A:D,4,FALSE) -> 5842385.1 | I13: =G13=H13 -> TRUE | L13: =VLOOKUP(B13,'Tally Balance'!A:E,5,FALSE) -> 0
A14: SAP India Pvt Ltd | B14: SB22540 | C14: =VLOOKUP(B14,'NS Balance'!D:F,3,FALSE) -> 40227753 | D14: =VLOOKUP(B14,'Tally Balance'!A:C,3,FALSE) -> 40227348 | E14: =C14=D14 -> FALSE | F14: Difference of 405 | G14: =VLOOKUP(B14,'NS Balance'!D:G,4,FALSE) -> 46041000 | H14: =VLOOKUP(B14,'Tally Balance'!A:D,4,FALSE) -> 46041000 | I14: =G14=H14 -> TRUE | L14: =VLOOKUP(B14,'Tally Balance'!A:E,5,FALSE) -> 5813652.2
A15: Thoughtworks Technologies India Pvt Ltd | B15: SB22443 | C15: =VLOOKUP(B15,'NS Balance'!D:F,3,FALSE) -> 14500 | D15: =VLOOKUP(B15,'Tally Balance'!A:C,3,FALSE) -> 14500 | E15: =C15=D15 -> TRUE | G15: =VLOOKUP(B15,'NS Balance'!D:G,4,FALSE) -> 14500 | H15: =VLOOKUP(B15,'Tally Balance'!A:D,4,FALSE) -> 14500 | I15: =G15=H15 -> TRUE | L15: =VLOOKUP(B15,'Tally Balance'!A:E,5,FALSE) -> 0
A16: Autodesk India Pvt Ltd | B16: SB22399 | C16: =VLOOKUP(B16,'NS Balance'!D:F,3,FALSE) -> 12350 | D16: =VLOOKUP(B16,'Tally Balance'!A:C,3,FALSE) -> 12350 | E16: =C16=D16 -> TRUE | G16: =VLOOKUP(B16,'NS Balance'!D:G,4,FALSE) -> 12350 | H16: =VLOOKUP(B16,'Tally Balance'!A:D,4,FALSE) -> 12350 | I16: =G16=H16 -> TRUE | L16: =VLOOKUP(B16,'Tally Balance'!A:E,5,FALSE) -> 0
A17: CA (India)Technologies Pvt Ltd | B17: SB22317 | C17: =VLOOKUP(B17,'NS Balance'!D:F,3,FALSE) -> 2031969.5 | D17: =VLOOKUP(B17,'Tally Balance'!A:C,3,FALSE) -> 2031969.5 | E17: =C17=D17 -> TRUE | G17: =VLOOKUP(B17,'NS Balance'!D:G,4,FALSE) -> 2031969.5 | H17: =VLOOKUP(B17,'Tally Balance'!A:D,4,FALSE) -> 2031969.5 | I17: =G17=H17 -> TRUE | L17: =VLOOKUP(B17,'Tally Balance'!A:E,5,FALSE) -> 0
A18: Hitachi Vantara India Pvt Ltd | B18: SB22223 | C18: =VLOOKUP(B18,'NS Balance'!D:F,3,FALSE) -> 142488 | D18: =VLOOKUP(B18,'Tally Balance'!A:C,3,FALSE) -> 142488 | E18: =C18=D18 -> TRUE | G18: =VLOOKUP(B18,'NS Balance'!D:G,4,FALSE) -> 142488 | H18: =VLOOKUP(B18,'Tally Balance'!A:D,4,FALSE) -> 142488 | I18: =G18=H18 -> TRUE | L18: =VLOOKUP(B18,'Tally Balance'!A:E,5,FALSE) -> 0
A19: Hitachi Vantara India Pvt Ltd | B19: SB22268 | C19: =VLOOKUP(B19,'NS Balance'!D:F,3,FALSE) -> 1834097 | D19: =VLOOKUP(B19,'Tally Balance'!A:C,3,FALSE) -> 1834097 | E19: =C19=D19 -> TRUE | G19: =VLOOKUP(B19,'NS Balance'!D:G,4,FALSE) -> 1834097 | H19: =VLOOKUP(B19,'Tally Balance'!A:D,4,FALSE) -> 1834097 | I19: =G19=H19 -> TRUE | L19: =VLOOKUP(B19,'Tally Balance'!A:E,5,FALSE) -> 0
A20: Hitachi Vantara India Pvt Ltd | B20: SB22321 | C20: =VLOOKUP(B20,'NS Balance'!D:F,3,FALSE) -> 500000 | D20: =VLOOKUP(B20,'Tally Balance'!A:C,3,FALSE) -> 500000 | E20: =C20=D20 -> TRUE | G20: =VLOOKUP(B20,'NS Balance'!D:G,4,FALSE) -> 516000 | H20: =VLOOKUP(B20,'Tally Balance'!A:D,4,FALSE) -> 516000 | I20: =G20=H20 -> TRUE | L20: =VLOOKUP(B20,'Tally Balance'!A:E,5,FALSE) -> 16000
A21: Hitachi Vantara India Pvt Ltd | B21: SB22545 | C21: =VLOOKUP(B21,'NS Balance'!D:F,3,FALSE) -> 2800020 | D21: =VLOOKUP(B21,'Tally Balance'!A:C,3,FALSE) -> 2800020 | E21: =C21=D21 -> TRUE | G21: =VLOOKUP(B21,'NS Balance'!D:G,4,FALSE) -> 2839466 | H21: =VLOOKUP(B21,'Tally Balance'!A:D,4,FALSE) -> 3500020 | I21: =G21=H21 -> FALSE | L21: =VLOOKUP(B21,'Tally Balance'!A:E,5,FALSE) -> 700000
A22: Hitachi Vantara India Pvt Ltd | B22: SB22580 | C22: =VLOOKUP(B22,'NS Balance'!D:F,3,FALSE) -> 650000 | D22: =VLOOKUP(B22,'Tally Balance'!A:C,3,FALSE) -> 650000 | E22: =C22=D22 -> TRUE | G22: =VLOOKUP(B22,'NS Balance'!D:G,4,FALSE) -> 650000 | H22: =VLOOKUP(B22,'Tally Balance'!A:D,4,FALSE) -> 650000 | I22: =G22=H22 -> TRUE | L22: =VLOOKUP(B22,'Tally Balance'!A:E,5,FALSE) -> 0
A23: Hitachi Vantara India Pvt Ltd | B23: SB22616 | C23: =VLOOKUP(B23,'NS Balance'!D:F,3,FALSE) -> 485000 | D23: =VLOOKUP(B23,'Tally Balance'!A:C,3,FALSE) -> 485000 | E23: =C23=D23 -> TRUE | G23: =VLOOKUP(B23,'NS Balance'!D:G,4,FALSE) -> 617954 | H23: =VLOOKUP(B23,'Tally Balance'!A:D,4,FALSE) -> 617954 | I23: =G23=H23 -> TRUE | L23: =VLOOKUP(B23,'Tally Balance'!A:E,5,FALSE) -> 132954
A24: Jamf India Pvt Ltd | B24: SB22485 | C24: =VLOOKUP(B24,'NS Balance'!D:F,3,FALSE) -> 3404033 | D24: =VLOOKUP(B24,'Tally Balance'!A:C,3,FALSE) -> 3404033 | E24: =C24=D24 -> TRUE | G24: =VLOOKUP(B24,'NS Balance'!D:G,4,FALSE) -> 3381121 | H24: =VLOOKUP(B24,'Tally Balance'!A:D,4,FALSE) -> 3381121 | I24: =G24=H24 -> TRUE | L24: =VLOOKUP(B24,'Tally Balance'!A:E,5,FALSE) -> 22912
A25: Jamf India Pvt Ltd | B25: SB22579 | C25: =VLOOKUP(B25,'NS Balance'!D:F,3,FALSE) -> 635518 | D25: =VLOOKUP(B25,'Tally Balance'!A:C,3,FALSE) -> 635518 | E25: =C25=D25 -> TRUE | G25: =VLOOKUP(B25,'NS Balance'!D:G,4,FALSE) -> 11800 | H25: =VLOOKUP(B25,'Tally Balance'!A:D,4,FALSE) -> 885518 | I25: =G25=H25 -> FALSE | L25: =VLOOKUP(B25,'Tally Balance'!A:E,5,FALSE) -> 250000
A26: Red Hat India Pvt Ltd | B26: SB22323 | C26: =VLOOKUP(B26,'NS Balance'!D:F,3,FALSE) -> 575640 | D26: =VLOOKUP(B26,'Tally Balance'!A:C,3,FALSE) -> 575640 | E26: =C26=D26 -> TRUE | G26: =VLOOKUP(B26,'NS Balance'!D:G,4,FALSE) -> 738000 | H26: =VLOOKUP(B26,'Tally Balance'!A:D,4,FALSE) -> 738000 | I26: =G26=H26 -> TRUE | L26: =VLOOKUP(B26,'Tally Balance'!A:E,5,FALSE) -> 162360
... A41: Dbs Bank India Ltd | B41: SB22416 | C41: =VLOOKUP(B41,'NS Balance'!D:F,3,FALSE) -> 6000 | D41: =VLOOKUP(B41,'Tally Balance'!A:C,3,FALSE) -> 6000 | E41: =C41=D41 -> TRUE | G41: =VLOOKUP(B41,'NS Balance'!D:G,4,FALSE) -> 6000 | H41: =VLOOKUP(B41,'Tally Balance'!A:D,4,FALSE) -> 6000 | I41: =G41=H41 -> TRUE | L41: =VLOOKUP(B41,'Tally Balance'!A:E,5,FALSE) -> 0
A42: Dbs Bank India Ltd | B42: SB22492 | C42: =VLOOKUP(B42,'NS Balance'!D:F,3,FALSE) -> 3135421 | D42: =VLOOKUP(B42,'Tally Balance'!A:C,3,FALSE) -> 3117506 | E42: =C42=D42 -> FALSE | F42: A/2025/PB/001469 - 17915.0 in NS | G42: =VLOOKUP(B42,'NS Balance'!D:G,4,FALSE) -> 2942744 | H42: =VLOOKUP(B42,'Tally Balance'!A:D,4,FALSE) -> 2942744 | I42: =G42=H42 -> TRUE | L42: =VLOOKUP(B42,'Tally Balance'!A:E,5,FALSE) -> 174761.96
A43: #N/A | B43: SB22506 | C43: =VLOOKUP(B43,'NS Balance'!D:F,3,FALSE) -> #N/A | D43: =VLOOKUP(B43,'Tally Balance'!A:C,3,FALSE) -> 0 | E43: =C43=D43 -> #N/A | G43: =VLOOKUP(B43,'NS Balance'!D:G,4,FALSE) -> #N/A | H43: =VLOOKUP(B43,'Tally Balance'!A:D,4,FALSE) -> 434 | I43: =G43=H43 -> #N/A | L43: =VLOOKUP(B43,'Tally Balance'!A:E,5,FALSE) -> 434
A44: Dbs Bank India Ltd | B44: SB22567 | C44: =VLOOKUP(B44,'NS Balance'!D:F,3,FALSE) -> 17503.2 | D44: =VLOOKUP(B44,'Tally Balance'!A:C,3,FALSE) -> 17503.2 | E44: =C44=D44 -> TRUE | G44: =VLOOKUP(B44,'NS Balance'!D:G,4,FALSE) -> 24145 | H44: =VLOOKUP(B44,'Tally Balance'!A:D,4,FALSE) -> 24145 | I44: =G44=H44 -> TRUE | L44: =VLOOKUP(B44,'Tally Balance'!A:E,5,FALSE) -> 6641.8
A45: Dbs Bank India Ltd | B45: SB22583 | C45: =VLOOKUP(B45,'NS Balance'!D:F,3,FALSE) -> 9728.8 | D45: =VLOOKUP(B45,'Tally Balance'!A:C,3,FALSE) -> 9728.8 | E45: =C45=D45 -> TRUE | G45: =VLOOKUP(B45,'NS Balance'!D:G,4,FALSE) -> 55000 | H45: =VLOOKUP(B45,'Tally Balance'!A:D,4,FALSE) -> 55000 | I45: =G45=H45 -> TRUE | L45: =VLOOKUP(B45,'Tally Balance'!A:E,5,FALSE) -> 45271.2
A46: Asus Global Pte Ltd | B46: SB22584 | C46: =VLOOKUP(B46,'NS Balance'!D:F,3,FALSE) -> 2629750 | D46: =VLOOKUP(B46,'Tally Balance'!A:C,3,FALSE) -> 2629750 | E46: =C46=D46 -> TRUE | G46: =VLOOKUP(B46,'NS Balance'!D:G,4,FALSE) -> 3174301.4 | H46: =VLOOKUP(B46,'Tally Balance'!A:D,4,FALSE) -> 3325307 | I46: =G46=H46 -> FALSE | L46: =VLOOKUP(B46,'Tally Balance'!A:E,5,FALSE) -> 695557
A47: BP Business Solutions India Pvt Ltd | B47: SB22564 | C47: =VLOOKUP(B47,'NS Balance'!D:F,3,FALSE) -> 666966.43 | D47: =VLOOKUP(B47,'Tally Balance'!A:C,3,FALSE) -> 666966.43 | E47: =C47=D47 -> TRUE | G47: =VLOOKUP(B47,'NS Balance'!D:G,4,FALSE) -> 1017327 | H47: =VLOOKUP(B47,'Tally Balance'!A:D,4,FALSE) -> 1017327 | I47: =G47=H47 -> TRUE | L47: =VLOOKUP(B47,'Tally Balance'!A:E,5,FALSE) -> 350360.57
A48: BP Business Solutions India Pvt Ltd | B48: SB22575 | C48: =VLOOKUP(B48,'NS Balance'!D:F,3,FALSE) -> 435524 | D48: =VLOOKUP(B48,'Tally Balance'!A:C,3,FALSE) -> 435524 | E48: =C48=D48 -> TRUE | G48: =VLOOKUP(B48,'NS Balance'!D:G,4,FALSE) -> 835524 | H48: =VLOOKUP(B48,'Tally Balance'!A:D,4,FALSE) -> 835524 | I48: =G48=H48 -> TRUE | L48: =VLOOKUP(B48,'Tally Balance'!A:E,5,FALSE) -> 400000
A49: BP Business Solutions India Pvt Ltd | B49: SB22582 | C49: =VLOOKUP(B49,'NS Balance'!D:F,3,FALSE) -> 88448 | D49: =VLOOKUP(B49,'Tally Balance'!A:C,3,FALSE) -> 88448 | E49: =C49=D49 -> TRUE | G49: =VLOOKUP(B49,'NS Balance'!D:G,4,FALSE) -> 138448 | H49: =VLOOKUP(B49,'Tally Balance'!A:D,4,FALSE) -> 138448 | I49: =G49=H49 -> TRUE | L49: =VLOOKUP(B49,'Tally Balance'!A:E,5,FALSE) -> 50000
A50: Citi Bank | B50: SB22536 | C50: =VLOOKUP(B50,'NS Balance'!D:F,3,FALSE) -> 10000 | D50: =VLOOKUP(B50,'Tally Balance'!A:C,3,FALSE) -> 10000 | E50: =C50=D50 -> TRUE | G50: =VLOOKUP(B50,'NS Balance'!D:G,4,FALSE) -> 0 | H50: =VLOOKUP(B50,'Tally Balance'!A:D,4,FALSE) -> 11000 | I50: =G50=H50 -> FALSE | L50: =VLOOKUP(B50,'Tally Balance'!A:E,5,FALSE) -> 1000
A51: Hindustan Unilever Ltd | B51: SB22324 | C51: =VLOOKUP(B51,'NS Balance'!D:F,3,FALSE) -> 1301935 | D51: =VLOOKUP(B51,'Tally Balance'!A:C,3,FALSE) -> 1301935 | E51: =C51=D51 -> TRUE | G51: =VLOOKUP(B51,'NS Balance'!D:G,4,FALSE) -> 1440862 | H51: =VLOOKUP(B51,'Tally Balance'!A:D,4,FALSE) -> 1440862 | I51: =G51=H51 -> TRUE | L51: =VLOOKUP(B51,'Tally Balance'!A:E,5,FALSE) -> 138927
A52: Hindustan Unilever Ltd | B52: SB22354 | C52: =VLOOKUP(B52,'NS Balance'!D:F,3,FALSE) -> 32000 | D52: =VLOOKUP(B52,'Tally Balance'!A:C,3,FALSE) -> 32000 | E52: =C52=D52 -> TRUE | G52: =VLOOKUP(B52,'NS Balance'!D:G,4,FALSE) -> 32000 | H52: =VLOOKUP(B52,'Tally Balance'!A:D,4,FALSE) -> 32000 | I52: =G52=H52 -> TRUE | L52: =VLOOKUP(B52,'Tally Balance'!A:E,5,FALSE) -> 0
A53: Hindustan Unilever Ltd | B53: SB22387 | C53: =VLOOKUP(B53,'NS Balance'!D:F,3,FALSE) -> 3500 | D53: =VLOOKUP(B53,'Tally Balance'!A:C,3,FALSE) -> 3500 | E53: =C53=D53 -> TRUE | G53: =VLOOKUP(B53,'NS Balance'!D:G,4,FALSE) -> 3500 | H53: =VLOOKUP(B53,'Tally Balance'!A:D,4,FALSE) -> 3500 | I53: =G53=H53 -> TRUE | L53: =VLOOKUP(B53,'Tally Balance'!A:E,5,FALSE) -> 0
A54: Hindustan Unilever Ltd | B54: SB22395 | C54: =VLOOKUP(B54,'NS Balance'!D:F,3,FALSE) -> 49700 | D54: =VLOOKUP(B54,'Tally Balance'!A:C,3,FALSE) -> 49700 | E54: =C54=D54 -> TRUE | G54: =VLOOKUP(B54,'NS Balance'!D:G,4,FALSE) -> 49700 | H54: =VLOOKUP(B54,'Tally Balance'!A:D,4,FALSE) -> 49700 | I54: =G54=H54 -> TRUE | L54: =VLOOKUP(B54,'Tally Balance'!A:E,5,FALSE) -> 0
...

Sheet NS Balance
A1: Location | B1: Department | C1: Customer | D1: Project | E1: Opening Balance | F1: Total Debit | G1: Total Credit | H1: Closing Balance
C2: 10008 Asia Pacific Travel Retail Association | F2: 4006150 | G2: 5861668 | H2: 1855518
D3: SB22437 | F3: 4006150 | G3: 5861668 | H3: 1855518
C4: 10043 Kiran Nadar Museum of Art | F4: 1000000 | G4: 1610670 | H4: 610670
D5: SB22598 | F5: 1000000 | G5: 1610670 | H5: 610670
C6: 10046 Lightspeed India Partners Advisors LLP | F6: 804498 | G6: 851135 | H6: 46637
D7: SB22392 | F7: 26000 | G7: 26000 | H7: 0
D8: SB22548 | F8: 778498 | G8: 825135 | H8: 46637
C9: 10088 CIO Association | F9: 374590 | G9: 374590 | H9: 0
D10: SB22444 | F10: 374590 | G10: 374590 | H10: 0
C11: 10108 Indian Electrical & Electronics | F11: 138800 | G11: 0 | H11: 138800
D12: SB22401 | F12: 138800 | G12: 0 | H12: 138800
C13: 10203 Accenture Solutions Pvt Ltd | F13: 3311878 | G13: 3873646.2 | H13: 1385530.2 | J13: =SUM(F14:F21) -> 3311878
D14: SB22632 | F14: 431402 | G14: 553080 | H14: 121678
D15: SB22600 | F15: 149700 | G15: 192016 | H15: 42316
D16: SB22511 | F16: 1800000 | G16: 2400000 | H16: 600000
D17: SB22376 | F17: 326914 | G17: 309507 | H17: 17407
D18: SB22570 | F18: 94380 | G18: 171050 | H18: 76670
D19: SB22526 | F19: 115008 | G19: 121792 | H19: 6784
D20: SB21386 | F20: 394474 | G20: 0 | H20: 394474
D21: SB22516 | F21: 0 | G21: 126201.2 | H21: 126201.2
C22: 10467 Adobe Systems India Pvt Ltd | F22: 1639500 | G22: 2845500 | H22: 1206000
D23: SB22414 | F23: 1389500 | G23: 1389500 | H23: 0
D24: SB22592 | F24: 250000 | G24: 1456000 | H24: 1206000
C25: 10555 Amazon Pay (India) Pvt Ltd | F25: 133500 | G25: 133500 | H25: 0
D26: SB22282 | F26: 133500 | G26: 133500 | H26: 0
C27: 10642 Amazon Seller Services India Pvt Ltd | F27: 1761018 | G27: 2469382 | H27: 708364
D28: SB22547 | F28: 42110 | G28: 42110 | H28: 0
D29: SB22635 | F29: 120000 | G29: 179520 | H29: 59520
D30: SB22589 | F30: 23000 | G30: 34100 | H30: 11100
D31: SB22652 | F31: 7500 | G31: 10010 | H31: 2510
D32: SB22504 | F32: 8391 | G32: 8681 | H32: 290
D33: SB22487 | F33: 36830 | G33: 36830 | H33: 0
D34: SB22524 | F34: 22800 | G34: 22800 | H34: 0
D35: SB22659 | F35: 140000 | G35: 178178 | H35: 38178
D36: SB22555 | F36: 15000 | G36: 15000 | H36: 0
D37: SB22604 | F37: 708765 | G37: 1014046 | H37: 305281
D38: SB22556 | F38: 52056 | G38: 52056 | H38: 0
D39: SB22573 | F39: 22000 | G39: 33583 | H39: 11583
... D45: SB22205 | F45: 0 | G45: 37050 | H45: 37050
...

Sheet Tally Balance
C1: Debit | D1: Credit | E1: Closing
A2: SB21386 | C2: 394474 | E2: 394474
A3: SB22376 | C3: 326914 | D3: 309507 | E3: 17407
A4: SB22511 | C4: 1800000 | D4: 2400000 | E4: 600000
A5: SB22526 | C5: 115008 | D5: 121792 | E5: 6784
A6: SB22570 | C6: 94380 | D6: 171050 | E6: 76670
A7: SB22600 | C7: 149700 | D7: 192016 | E7: 42316
A8: SB22632 | C8: 431402 | D8: 553080 | E8: 121678
A9: BU1R
A10: ClarivateAnalyticsIndiaPvtLtd-BU1R | C10: 511290 | D10: 771075 | E10: 259785
A11: ClarivateAnalyticsIndiaPvtLtd-BU1R
A12: SB22581 | C12: 511290 | D12: 771075 | E12: 259785
A13: IndianExplosivesPvtLtd(Dr)-Mum | C13: 83600 | D13: 83600
A14: IndianExplosivesPvtLtd(Dr)-Mum
A15: SB22347 | C15: 83600 | D15: 83600
A16: NttDataBusinessSolutionsPvtLtd-(Dr)-Mum | C16: 727110 | D16: 1155224 | E16: 428114
A17: NttDataBusinessSolutionsPvtLtd-(Dr)-Mum
A18: SB22384 | C18: 727110 | D18: 1155224 | E18: 428114
A19: SAPIndiaPvt.Ltd.-BU1R | C19: 47615188 | D19: 53428840 | E19: 5813652.2
A20: SAPIndiaPvt.Ltd.-BU1R
A21: SB22124 | C21: 1545455 | D21: 1545455
A22: SB22428 | C22: 5842385.1 | D22: 5842385.1
A23: SB22540 | C23: 40227348 | D23: 46041000 | E23: 5813652.2
A24: ThoughtworksTechnologiesIndiaPvtLtd-BU1R | C24: 14500 | D24: 14500
A25: ThoughtworksTechnologiesIndiaPvtLtd-BU1R
A26: SB22443 | C26: 14500 | D26: 14500
A27: BU1Sohan | C27: 26782138 | D27: 30515420 | E27: 3733281.9
A28: AutodeskIndiaPvtLtd-BU1 | C28: 12350 | D28: 12350
A29: AutodeskIndiaPvtLtd-BU1
A30: SB22399 | C30: 12350 | D30: 12350
A31: BU1Sohan
A32: CA(India)TechnologiesPvtLtd(DR)-Mum | C32: 2031969.5 | D32: 2031969.5
A33: CA(India)TechnologiesPvtLtd(DR)-Mum
A34: SB22317 | C34: 2031969.5 | D34: 2031969.5
A35: HitachiVantaraIndiaPrivateLimited-BU1Sohan | C35: 6411605 | D35: 7260559 | E35: 848954
A36: HitachiVantaraIndiaPrivateLimited-BU1Sohan
A37: SB22223 | C37: 142488 | D37: 142488
A38: SB22268 | C38: 1834097 | D38: 1834097
A39: SB22321 | C39: 500000 | D39: 516000 | E39: 16000
A40: SB22545 | C40: 2800020 | D40: 3500020 | E40: 700000
...

Sheet Sheet1
B3: 727110 | C3: 727580 | D3: =B3-C3 -> #VALUE!
