Workbook

Sheet COGS Item and GL
A1: Item Name | B1: Account Name | C1: Number | D1: Internal ID Prod | E1: Display Name
A2: Advertisement Expenses | B2: 10166 ADVERTISEMENT EXPENSES | C2: =_xlfn.TEXTBEFORE(B2," ") -> 10166 | D2: =VLOOKUP(C2,Sheet1!C:E,2,FALSE) -> 678 | E2: =VLOOKUP(C2,Sheet1!C:E,3,FALSE) -> 10166 OWN ADVERTISING : ADVERTISEMENT EXPENSES | F2: =VLOOKUP(D2,Sheet3!B:C,2,FALSE) -> Expense
A3: Air Cargo Charges - Events | B3: 1040 Air Cargo Charges - Events | C3: =_xlfn.TEXTBEFORE(B3," ") -> 1040 | D3: =VLOOKUP(C3,Sheet1!C:E,2,FALSE) -> 1254 | E3: =VLOOKUP(C3,Sheet1!C:E,3,FALSE) -> 1040 DIRECT REBILLED COSTS (OTHER THAN MEDIA)A : EVENT MNG ORG CHARGES : Air Cargo Charges - Events | F3: =VLOOKUP(D3,Sheet3!B:C,2,FALSE) -> Cost of Goods Sold
A4: Air Fare | B4: 10149 AIR TRAVEL FARE | C4: =_xlfn.TEXTBEFORE(B4," ") -> 10149 | D4: =VLOOKUP(C4,Sheet1!C:E,2,FALSE) -> 661 | E4: =VLOOKUP(C4,Sheet1!C:E,3,FALSE) -> 10149 TRAVEL COSTS : AIR TRAVEL FARE | F4: =VLOOKUP(D4,Sheet3!B:C,2,FALSE) -> Expense
A5: Air Fare - Events | B5: 1042 Air Fare - Events | C5: =_xlfn.TEXTBEFORE(B5," ") -> 1042 | D5: =VLOOKUP(C5,Sheet1!C:E,2,FALSE) -> 1256 | E5: =VLOOKUP(C5,Sheet1!C:E,3,FALSE) -> 1042 DIRECT REBILLED COSTS (OTHER THAN MEDIA)A : EVENT MNG ORG CHARGES : Air Fare - Events | F5: =VLOOKUP(D5,Sheet3!B:C,2,FALSE) -> Cost of Goods Sold
A6: Air Transport | B6: 10149 AIR TRAVEL FARE | C6: =_xlfn.TEXTBEFORE(B6," ") -> 10149 | D6: =VLOOKUP(C6,Sheet1!C:E,2,FALSE) -> 661 | E6: =VLOOKUP(C6,Sheet1!C:E,3,FALSE) -> 10149 TRAVEL COSTS : AIR TRAVEL FARE | F6: =VLOOKUP(D6,Sheet3!B:C,2,FALSE) -> Expense
A7: Air Travel Fare | B7: 10149 AIR TRAVEL FARE | C7: =_xlfn.TEXTBEFORE(B7," ") -> 10149 | D7: =VLOOKUP(C7,Sheet1!C:E,2,FALSE) -> 661 | E7: =VLOOKUP(C7,Sheet1!C:E,3,FALSE) -> 10149 TRAVEL COSTS : AIR TRAVEL FARE | F7: =VLOOKUP(D7,Sheet3!B:C,2,FALSE) -> Expense
A8: Asset Maintainance Charges | B8: 10113 ASSET MAINTAINANCE CHARGES | C8: =_xlfn.TEXTBEFORE(B8," ") -> 10113 | D8: =VLOOKUP(C8,Sheet1!C:E,2,FALSE) -> 625 | E8: =VLOOKUP(C8,Sheet1!C:E,3,FALSE) -> 10113 REAL PROPERTY SERVICE EXPENSES (EXPENSES) / INCOME : ASSET MAINTAINANCE CHARGES | F8: =VLOOKUP(D8,Sheet3!B:C,2,FALSE) -> Expense
A9: Auditors Remuneration | B9: 10120 AUDITORS REMUNERATION | C9: =_xlfn.TEXTBEFORE(B9," ") -> 10120 | D9: =VLOOKUP(C9,Sheet1!C:E,2,FALSE) -> 632 | E9: =VLOOKUP(C9,Sheet1!C:E,3,FALSE) -> 10120 FEES AND SUBSCRIPTION FEES : AUDITORS REMUNERATION | F9: =VLOOKUP(D9,Sheet3!B:C,2,FALSE) -> Expense
A10: Business Development Charges | B10: 1005 Business Development Charges | C10: =_xlfn.TEXTBEFORE(B10," ") -> 1005 | D10: =VLOOKUP(C10,Sheet1!C:E,2,FALSE) -> 1219 | E10: =VLOOKUP(C10,Sheet1!C:E,3,FALSE) -> 1005 DIRECT REBILLED COSTS (OTHER THAN MEDIA)A : EVENT MNG ORG CHARGES : Business Development Charges | F10: =VLOOKUP(D10,Sheet3!B:C,2,FALSE) -> Cost of Goods Sold
A11: Car Hire Charges - Events | B11: 1043 Car Hire Charges - Events | C11: =_xlfn.TEXTBEFORE(B11," ") -> 1043 | D11: =VLOOKUP(C11,Sheet1!C:E,2,FALSE) -> 1257 | E11: =VLOOKUP(C11,Sheet1!C:E,3,FALSE) -> 1043 DIRECT REBILLED COSTS (OTHER THAN MEDIA)A : EVENT MNG ORG CHARGES : Car Hire Charges - Events | F11: =VLOOKUP(D11,Sheet3!B:C,2,FALSE) -> Cost of Goods Sold
A12: Car Hire Expenses | B12: 10152 CAR HIRE EXPENSES | C12: =_xlfn.TEXTBEFORE(B12," ") -> 10152 | D12: =VLOOKUP(C12,Sheet1!C:E,2,FALSE) -> 664 | E12: =VLOOKUP(C12,Sheet1!C:E,3,FALSE) -> 10152 TRAVEL COSTS : CAR HIRE EXPENSES | F12: =VLOOKUP(D12,Sheet3!B:C,2,FALSE) -> Expense
A13: Car Hire Expenses | B13: 10152 CAR HIRE EXPENSES | C13: =_xlfn.TEXTBEFORE(B13," ") -> 10152 | D13: =VLOOKUP(C13,Sheet1!C:E,2,FALSE) -> 664 | E13: =VLOOKUP(C13,Sheet1!C:E,3,FALSE) -> 10152 TRAVEL COSTS : CAR HIRE EXPENSES | F13: =VLOOKUP(D13,Sheet3!B:C,2,FALSE) -> Expense
... A114: Water Charges | B114: 10117 WATER CHARGES | C114: =_xlfn.TEXTBEFORE(B114," ") -> 10117 | D114: =VLOOKUP(C114,Sheet1!C:E,2,FALSE) -> 629 | E114: =VLOOKUP(C114,Sheet1!C:E,3,FALSE) -> 10117 REAL PROPERTY SERVICE EXPENSES (EXPENSES) / INCOME : WATER CHARGES | F114: =VLOOKUP(D114,Sheet3!B:C,2,FALSE) -> Expense

Sheet Income Item and GL
A1: Item Name | B1: Account Name | C1: Internal ID Prod
A2: Sales | B2: EVENT MNG ORG REVENUE | C2: 535
A3: Event Revenue | B3: EVENT MNG ORG REVENUE : Event Revenue | C3: 1215
A4: Inter Office Revenue | B4: EVENT MNG ORG REVENUE : Inter Office Revenue | C4: 1216
A5: Sponsorship Fees | B5: EVENT MNG ORG REVENUE : Sponsorship Revenue | C5: 1244
A6: MISCELLANEOUS EXPENSES WRITTEN OFF | B6: Miscellaneous Expenses Written Off for Sale | C6: 720

Sheet AP & AR GL
A1: Account Name | B1: Internal ID Prod
A2: Account Receivable | B2: 119
A3: Sundry Debtors | B3: 874
A4: Account Paybles | B4: 111
A5: 10530 Accounts Payble | B5: 1040
A6: Advance to Employee | B6: 1454
A7: Loan to Employee | B7: 850 , 853 , 952

Sheet Sheet1
A1: Internal ID | B1: Name | C1: Number | D1: Internal ID | E1: Display Name | F1: Account Type | G1: Description | H1: Balance | I1: Show in Fixed Assets Management | J1: Employee
A2: 111 | B2: Accounts Payable | D2: 111 | E2: Accounts Payable | F2: Accounts Payable | H2: -1.0137171e+09
A3: 434 | B3: ACCOUNTS PAYABLE | C3: P40000 | D3: 434 | E3: P40000 ACCOUNTS PAYABLE | F3: Accounts Payable | H3: 0
A4: 1040 | B4: ACCOUNTS PAYABLE : ACCOUNTS PAYABLE | C4: 10530 | D4: 1040 | E4: 10530 ACCOUNTS PAYABLE : ACCOUNTS PAYABLE | F4: Accounts Payable | H4: -39605554
A5: 1453 | B5: ACCOUNTS PAYABLE : ACCOUNTS PAYABLE : Credit Card Dues (MIS) | C5: 1251 | D5: 1453 | E5: 1251 ACCOUNTS PAYABLE : ACCOUNTS PAYABLE : Credit Card Dues (MIS) | F5: Accounts Payable | H5: 0
A6: 1333 | B6: ACCOUNTS PAYABLE : ACCOUNTS PAYABLE : Executive Advance For Expenses Payable (Mis) | C6: 1119 | D6: 1333 | E6: 1119 ACCOUNTS PAYABLE : ACCOUNTS PAYABLE : Executive Advance For Expenses Payable (Mis) | F6: Accounts Payable | H6: 9599
A7: 1048 | B7: ACCOUNTS PAYABLE : ADVANCE BILLING | C7: 10538 | D7: 1048 | E7: 10538 ACCOUNTS PAYABLE : ADVANCE BILLING | F7: Accounts Payable | H7: 0
A8: 1046 | B8: ACCOUNTS PAYABLE : DEFERRED LEASE RENT LIABILITY | C8: 10536 | D8: 1046 | E8: 10536 ACCOUNTS PAYABLE : DEFERRED LEASE RENT LIABILITY | F8: Accounts Payable | H8: 0
A9: 1042 | B9: ACCOUNTS PAYABLE : OUTSTANDING LIABILITIES | C9: 10532 | D9: 1042 | E9: 10532 ACCOUNTS PAYABLE : OUTSTANDING LIABILITIES | F9: Accounts Payable | H9: 0
A10: 1044 | B10: ACCOUNTS PAYABLE : PROV. FOR BILLS PAYABLE (SHORT IBS) | C10: 10534 | D10: 1044 | E10: 10534 ACCOUNTS PAYABLE : PROV. FOR BILLS PAYABLE (SHORT IBS) | F10: Accounts Payable | H10: 0
A11: 1045 | B11: ACCOUNTS PAYABLE : PROV. FOR COMMISSION/DISCOUNT PAYBLE | C11: 10535 | D11: 1045 | E11: 10535 ACCOUNTS PAYABLE : PROV. FOR COMMISSION/DISCOUNT PAYBLE | F11: Accounts Payable | H11: 0
A12: 1043 | B12: ACCOUNTS PAYABLE : PROV. FOR MANEGEMENT FEES | C12: 10533 | D12: 1043 | E12: 10533 ACCOUNTS PAYABLE : PROV. FOR MANEGEMENT FEES | F12: Accounts Payable | H12: 0
A13: 1041 | B13: ACCOUNTS PAYABLE : PROVISION AGAINST WORK IN PROGRESS | C13: 10531 | D13: 1041 | E13: 10531 ACCOUNTS PAYABLE : PROVISION AGAINST WORK IN PROGRESS | F13: Accounts Payable | H13: 0
A14: 1047 | B14: ACCOUNTS PAYABLE : SUSPENSE ACCOUNT | C14: 10537 | D14: 1047 | E14: 10537 ACCOUNTS PAYABLE : SUSPENSE ACCOUNT | F14: Accounts Payable | H14: 640316.71
A15: 119 | B15: Accounts Receivable | D15: 119 | E15: Accounts Receivable | F15: Accounts Receivable | H15: 1.5241973e+09
A16: 427 | B16: ACCRUED INTEREST ON BANK BORROWINGS | C16: P16887 | D16: 427 | E16: P16887 ACCRUED INTEREST ON BANK BORROWINGS | F16: Other Current Liability | H16: 0
A17: 1032 | B17: ACCRUED INTEREST ON BANK BORROWINGS : ACCRUED INTEREST ON BANK BORROWINGS | C17: 10522 | D17: 1032 | E17: 10522 ACCRUED INTEREST ON BANK BORROWINGS : ACCRUED INTEREST ON BANK BORROWINGS | F17: Other Current Liability | H17: 0
A18: 338 | B18: ACCRUED INTEREST ON OUTSIDE GROUP > 1YEAR | C18: A26781 | D18: 338 | E18: A26781 ACCRUED INTEREST ON OUTSIDE GROUP > 1YEAR | F18: Other Asset | H18: 0
A19: 1214 | B19: ACCRUED INTEREST ON OUTSIDE GROUP > 1YEAR : ACCRUED INTEREST ON OUTSIDE GROUP > 1YEAR | C19: 10337 | D19: 1214 | E19: 10337 ACCRUED INTEREST ON OUTSIDE GROUP > 1YEAR : ACCRUED INTEREST ON OUTSIDE GROUP > 1YEAR | F19: Other Asset | H19: 0
A20: 337 | B20: ACCRUED INTEREST ON OUTSIDE GROUP < 1YEAR | C20: A26780 | D20: 337 | E20: A26780 ACCRUED INTEREST ON OUTSIDE GROUP < 1YEAR | F20: Other Asset | H20: 0
A21: 1213 | B21: ACCRUED INTEREST ON OUTSIDE GROUP < 1YEAR : ACCRUED INTEREST ON OUTSIDE GROUP < 1YEAR | C21: 10336 | D21: 1213 | E21: 10336 ACCRUED INTEREST ON OUTSIDE GROUP < 1YEAR : ACCRUED INTEREST ON OUTSIDE GROUP < 1YEAR | F21: Other Asset | H21: 0
A22: 433 | B22: ACCRUED INTEREST ON OUTSIDE GROUP OVERDRAFT | C22: P51980 | D22: 433 | E22: P51980 ACCRUED INTEREST ON OUTSIDE GROUP OVERDRAFT | F22: Other Current Liability | H22: 0
A23: 1039 | B23: ACCRUED INTEREST ON OUTSIDE GROUP OVERDRAFT : ACCRUED INTEREST ON OUTSIDE GROUP OVERDRAFT | C23: 10529 | D23: 1039 | E23: 10529 ACCRUED INTEREST ON OUTSIDE GROUP OVERDRAFT : ACCRUED INTEREST ON OUTSIDE GROUP OVERDRAFT | F23: Other Current Liability | H23: 0
A24: 112 | B24: Accrued Purchases | D24: 112 | E24: Accrued Purchases | F24: Other Current Liability | H24: 0
A25: 440 | B25: ACCRUED SEVERANCES | C25: P42100 | D25: 440 | E25: P42100 ACCRUED SEVERANCES | F25: Other Current Liability | H25: 0
A26: 1071 | B26: ACCRUED SEVERANCES : ACCRUED SEVERANCES | C26: 10561 | D26: 1071 | E26: 10561 ACCRUED SEVERANCES : ACCRUED SEVERANCES | F26: Other Current Liability | H26: 0
A27: 290 | B27: ACQUISITION COSTS ON INVESTMENTS | C27: R66300 | D27: 290 | E27: R66300 ACQUISITION COSTS ON INVESTMENTS | F27: Expense | H27: 0
A28: 774 | B28: ACQUISITION COSTS ON INVESTMENTS : LOSSES ON FINANCIAL RECEIV AND INVEST SECURITIES | C28: 10262 | D28: 774 | E28: 10262 ACQUISITION COSTS ON INVESTMENTS : LOSSES ON FINANCIAL RECEIV AND INVEST SECURITIES | F28: Expense | H28: 0 | I28: Depreciation Expense,Disposal Cost Account,Write Down Account,Write Off Account
A29: 403 | B29: ACTUARIAL GAINS AND LOSSES | C29: P10602 | D29: 403 | E29: P10602 ACTUARIAL GAINS AND LOSSES | F29: Equity | H29: 0
A30: 1008 | B30: ACTUARIAL GAINS AND LOSSES : ACTUARIAL GAINS AND LOSSES | C30: 10498 | D30: 1008 | E30: 10498 ACTUARIAL GAINS AND LOSSES : ACTUARIAL GAINS AND LOSSES | F30: Equity | H30: 0
A31: 435 | B31: ADVANCE PAYMENTS FROM CLIENTS | C31: P40110 | D31: 435 | E31: P40110 ADVANCE PAYMENTS FROM CLIENTS | F31: Other Current Liability | H31: 0
A32: 1049 | B32: ADVANCE PAYMENTS FROM CLIENTS : ADVANCE RECEIVED FROM DEBTORS | C32: 10539 | D32: 1049 | E32: 10539 ADVANCE PAYMENTS FROM CLIENTS : ADVANCE RECEIVED FROM DEBTORS | F32: Other Current Liability | H32: 0
A33: 2387 | B33: Advance received from debtors | D33: 2387 | E33: Advance received from debtors | F33: Other Current Liability | H33: -3.2819298e+08
A34: 118 | B34: Advances Paid | D34: 118 | E34: Advances Paid | F34: Other Current Asset | H34: -210364
A35: 357 | B35: ADVANCES TO SUPPLIERS | C35: A40910 | D35: 357 | E35: A40910 ADVANCES TO SUPPLIERS | F35: Other Current Liability | H35: 0
A36: 873 | B36: ADVANCES TO SUPPLIERS : ADVANCES TO SUPPLIERS | C36: 10363 | D36: 873 | E36: 10363 ADVANCES TO SUPPLIERS : ADVANCES TO SUPPLIERS | F36: Other Current Liability | H36: 76124396
A37: 378 | B37: ALLOWANCE FOR ADV.SUPPLIERS | C37: A49091 | D37: 378 | E37: A49091 ALLOWANCE FOR ADV.SUPPLIERS | F37: Other Current Asset | H37: 0
A38: 956 | B38: ALLOWANCE FOR ADV.SUPPLIERS : ALLOWANCE FOR ADV.SUPPLIERS | C38: 10446 | D38: 956 | E38: 10446 ALLOWANCE FOR ADV.SUPPLIERS : ALLOWANCE FOR ADV.SUPPLIERS | F38: Other Current Asset | H38: 0
A39: 381 | B39: ALLOWANCE FOR DEFERRED TAX ASSET - DEFERRED DEDUCT. EXP. | C39: A49445 | D39: 381 | E39: A49445 ALLOWANCE FOR DEFERRED TAX ASSET - DEFERRED DEDUCT. EXP. | F39: Other Current Asset | H39: 0
A40: 960 | B40: ALLOWANCE FOR DEFERRED TAX ASSET - DEFERRED DEDUCT. EXP. : ALLOWANCE FOR DEFERRED TAX ASSET - DEFERRED DEDUCT. EXP. | C40: 10450 | D40: 960 | E40: 10450 ALLOWANCE FOR DEFERRED TAX ASSET - DEFERRED DEDUCT. EXP. : ALLOWANCE FOR DEFERRED TAX ASSET - DEFERRED DEDUCT. EXP. | F40: Other Current Asset | H40: 0
...

Sheet Sheet2
A1: Internal ID Prod
A2: 678
A3: 1254
A4: 661
A5: 1256
A6: 661
A7: 661
A8: 625
A9: 632
A10: 1219
A11: 1257
A12: 664
A13: 664
... A127: 952

Sheet Sheet3
A1: Internal ID | B1: Internal ID | C1: Account Type | D1: Name | E1: Display Name | F1: Account Type | G1: Description | H1: Balance | I1: Show in Fixed Assets Management | J1: Employee
A2: 111 | B2: 111 | C2: Accounts Payable | D2: Accounts Payable | E2: Accounts Payable | F2: Accounts Payable | H2: -1.0136452e+09
A3: 434 | B3: 434 | C3: Accounts Payable | D3: ACCOUNTS PAYABLE | E3: P40000 ACCOUNTS PAYABLE | F3: Accounts Payable | H3: 0
A4: 1040 | B4: 1040 | C4: Accounts Payable | D4: ACCOUNTS PAYABLE : ACCOUNTS PAYABLE | E4: 10530 ACCOUNTS PAYABLE : ACCOUNTS PAYABLE | F4: Accounts Payable | H4: -39780508
A5: 1453 | B5: 1453 | C5: Accounts Payable | D5: ACCOUNTS PAYABLE : ACCOUNTS PAYABLE : Credit Card Dues (MIS) | E5: 1251 ACCOUNTS PAYABLE : ACCOUNTS PAYABLE : Credit Card Dues (MIS) | F5: Accounts Payable | H5: 0
A6: 1333 | B6: 1333 | C6: Accounts Payable | D6: ACCOUNTS PAYABLE : ACCOUNTS PAYABLE : Executive Advance For Expenses Payable (Mis) | E6: 1119 ACCOUNTS PAYABLE : ACCOUNTS PAYABLE : Executive Advance For Expenses Payable (Mis) | F6: Accounts Payable | H6: 9599
A7: 1048 | B7: 1048 | C7: Accounts Payable | D7: ACCOUNTS PAYABLE : ADVANCE BILLING | E7: 10538 ACCOUNTS PAYABLE : ADVANCE BILLING | F7: Accounts Payable | H7: 0
A8: 1046 | B8: 1046 | C8: Accounts Payable | D8: ACCOUNTS PAYABLE : DEFERRED LEASE RENT LIABILITY | E8: 10536 ACCOUNTS PAYABLE : DEFERRED LEASE RENT LIABILITY | F8: Accounts Payable | H8: 0
A9: 1042 | B9: 1042 | C9: Accounts Payable | D9: ACCOUNTS PAYABLE : OUTSTANDING LIABILITIES | E9: 10532 ACCOUNTS PAYABLE : OUTSTANDING LIABILITIES | F9: Accounts Payable | H9: 0
A10: 1044 | B10: 1044 | C10: Accounts Payable | D10: ACCOUNTS PAYABLE : PROV. FOR BILLS PAYABLE (SHORT IBS) | E10: 10534 ACCOUNTS PAYABLE : PROV. FOR BILLS PAYABLE (SHORT IBS) | F10: Accounts Payable | H10: 0
A11: 1045 | B11: 1045 | C11: Accounts Payable | D11: ACCOUNTS PAYABLE : PROV. FOR COMMISSION/DISCOUNT PAYBLE | E11: 10535 ACCOUNTS PAYABLE : PROV. FOR COMMISSION/DISCOUNT PAYBLE | F11: Accounts Payable | H11: 0
A12: 1043 | B12: 1043 | C12: Accounts Payable | D12: ACCOUNTS PAYABLE : PROV. FOR MANEGEMENT FEES | E12: 10533 ACCOUNTS PAYABLE : PROV. FOR MANEGEMENT FEES | F12: Accounts Payable | H12: 0
A13: 1041 | B13: 1041 | C13: Accounts Payable | D13: ACCOUNTS PAYABLE : PROVISION AGAINST WORK IN PROGRESS | E13: 10531 ACCOUNTS PAYABLE : PROVISION AGAINST WORK IN PROGRESS | F13: Accounts Payable | H13: 0
... A27: 290 | B27: 290 | C27: Expense | D27: ACQUISITION COSTS ON INVESTMENTS | E27: R66300 ACQUISITION COSTS ON INVESTMENTS | F27: Expense | H27: 0
A28: 774 | B28: 774 | C28: Expense | D28: ACQUISITION COSTS ON INVESTMENTS : LOSSES ON FINANCIAL RECEIV AND INVEST SECURITIES | E28: 10262 ACQUISITION COSTS ON INVESTMENTS : LOSSES ON FINANCIAL RECEIV AND INVEST SECURITIES | F28: Expense | H28: 0 | I28: Depreciation Expense,Disposal Cost Account,Write Down Account,Write Off Account
A29: 403 | B29: 403 | C29: Equity | D29: ACTUARIAL GAINS AND LOSSES | E29: P10602 ACTUARIAL GAINS AND LOSSES | F29: Equity | H29: 0
A30: 1008 | B30: 1008 | C30: Equity | D30: ACTUARIAL GAINS AND LOSSES : ACTUARIAL GAINS AND LOSSES | E30: 10498 ACTUARIAL GAINS AND LOSSES : ACTUARIAL GAINS AND LOSSES | F30: Equity | H30: 0
A31: 435 | B31: 435 | C31: Other Current Liability | D31: ADVANCE PAYMENTS FROM CLIENTS | E31: P40110 ADVANCE PAYMENTS FROM CLIENTS | F31: Other Current Liability | H31: 0
A32: 1049 | B32: 1049 | C32: Other Current Liability | D32: ADVANCE PAYMENTS FROM CLIENTS : ADVANCE RECEIVED FROM DEBTORS | E32: 10539 ADVANCE PAYMENTS FROM CLIENTS : ADVANCE RECEIVED FROM DEBTORS | F32: Other Current Liability | H32: 0
A33: 2387 | B33: 2387 | C33: Other Current Liability | D33: Advance received from debtors | E33: Advance received from debtors | F33: Other Current Liability | H33: -3.4158146e+08
A34: 118 | B34: 118 | C34: Other Current Asset | D34: Advances Paid | E34: Advances Paid | F34: Other Current Asset | H34: -210364
A35: 357 | B35: 357 | C35: Other Current Liability | D35: ADVANCES TO SUPPLIERS | E35: A40910 ADVANCES TO SUPPLIERS | F35: Other Current Liability | H35: 0
A36: 873 | B36: 873 | C36: Other Current Liability | D36: ADVANCES TO SUPPLIERS : ADVANCES TO SUPPLIERS | E36: 10363 ADVANCES TO SUPPLIERS : ADVANCES TO SUPPLIERS | F36: Other Current Liability | H36: 76124396
A37: 378 | B37: 378 | C37: Other Current Asset | D37: ALLOWANCE FOR ADV.SUPPLIERS | E37: A49091 ALLOWANCE FOR ADV.SUPPLIERS | F37: Other Current Asset | H37: 0
A38: 956 | B38: 956 | C38: Other Current Asset | D38: ALLOWANCE FOR ADV.SUPPLIERS : ALLOWANCE FOR ADV.SUPPLIERS | E38: 10446 ALLOWANCE FOR ADV.SUPPLIERS : ALLOWANCE FOR ADV.SUPPLIERS | F38: Other Current Asset | H38: 0
A39: 381 | B39: 381 | C39: Other Current Asset | D39: ALLOWANCE FOR DEFERRED TAX ASSET - DEFERRED DEDUCT. EXP. | E39: A49445 ALLOWANCE FOR DEFERRED TAX ASSET - DEFERRED DEDUCT. EXP. | F39: Other Current Asset | H39: 0
A40: 960 | B40: 960 | C40: Other Current Asset | D40: ALLOWANCE FOR DEFERRED TAX ASSET - DEFERRED DEDUCT. EXP. : ALLOWANCE FOR DEFERRED TAX ASSET - DEFERRED DEDUCT. EXP. | E40: 10450 ALLOWANCE FOR DEFERRED TAX ASSET - DEFERRED DEDUCT. EXP. : ALLOWANCE FOR DEFERRED TAX ASSET - DEFERRED DEDUCT. EXP. | F40: Other Current Asset | H40: 0
... A43: 259 | B43: 259 | C43: Expense | D43: AMORT/DEPREC OF INTANGIBLE ASSETS | E43: R68114 AMORT/DEPREC OF INTANGIBLE ASSETS | F43: Expense | H43: 0
A44: 717 | B44: 717 | C44: Expense | D44: AMORT/DEPREC OF INTANGIBLE ASSETS : DEPRECIATION - INTANGIBLE ASSETS | E44: 10205 AMORT/DEPREC OF INTANGIBLE ASSETS : DEPRECIATION - INTANGIBLE ASSETS | F44: Expense | H44: 282482 | I44: Depreciation Expense,Disposal Cost Account,Write Down Account,Write Off Account
A45: 258 | B45: 258 | C45: Expense | D45: AMORT/DEPREC OF TANGIBLE ASSETS | E45: R68111 AMORT/DEPREC OF TANGIBLE ASSETS | F45: Expense | H45: 0
A46: 710 | B46: 710 | C46: Expense | D46: AMORT/DEPREC OF TANGIBLE ASSETS : DEPRECIATION - COMPUTERS | E46: 10198 AMORT/DEPREC OF TANGIBLE ASSETS : DEPRECIATION - COMPUTERS | F46: Expense | H46: 16495177 | I46: Depreciation Expense,Disposal Cost Account,Write Down Account,Write Off Account
A47: 712 | B47: 712 | C47: Expense | D47: AMORT/DEPREC OF TANGIBLE ASSETS : DEPRECIATION - F&F | E47: 10200 AMORT/DEPREC OF TANGIBLE ASSETS : DEPRECIATION - F&F | F47: Expense | H47: 254208 | I47: Depreciation Expense,Disposal Cost Account,Write Down Account,Write Off Account
A48: 716 | B48: 716 | C48: Expense | D48: AMORT/DEPREC OF TANGIBLE ASSETS : DEPRECIATION - LEASED VEHICLES | E48: 10204 AMORT/DEPREC OF TANGIBLE ASSETS : DEPRECIATION - LEASED VEHICLES | F48: Expense | H48: 0 | I48: Depreciation Expense,Disposal Cost Account,Write Down Account,Write Off Account
A49: 715 | B49: 715 | C49: Expense | D49: AMORT/DEPREC OF TANGIBLE ASSETS : DEPRECIATION - LEASEDHOLD IMPROVEMENTS | E49: 10203 AMORT/DEPREC OF TANGIBLE ASSETS : DEPRECIATION - LEASEDHOLD IMPROVEMENTS | F49: Expense | H49: 444815 | I49: Depreciation Expense,Disposal Cost Account,Write Down Account,Write Off Account
A50: 711 | B50: 711 | C50: Expense | D50: AMORT/DEPREC OF TANGIBLE ASSETS : DEPRECIATION - OFFICE EQPMT | E50: 10199 AMORT/DEPREC OF TANGIBLE ASSETS : DEPRECIATION - OFFICE EQPMT | F50: Expense | H50: 1151869 | I50: Depreciation Expense,Disposal Cost Account,Write Down Account,Write Off Account
A51: 714 | B51: 714 | C51: Expense | D51: AMORT/DEPREC OF TANGIBLE ASSETS : DEPRECIATION - SOFTWARE | E51: 10202 AMORT/DEPREC OF TANGIBLE ASSETS : DEPRECIATION - SOFTWARE | F51: Expense | H51: 6450 | I51: Depreciation Expense,Disposal Cost Account,Write Down Account,Write Off Account
A52: 713 | B52: 713 | C52: Expense | D52: AMORT/DEPREC OF TANGIBLE ASSETS : DEPRECIATION - VEHICLES | E52: 10201 AMORT/DEPREC OF TANGIBLE ASSETS : DEPRECIATION - VEHICLES | F52: Expense | H52: 0 | I52: Depreciation Expense,Disposal Cost Account,Write Down Account,Write Off Account
A53: 260 | B53: 260 | C53: Expense | D53: AMORTIZATION OF DEFERRED EXPENSES | E53: R68120 AMORTIZATION OF DEFERRED EXPENSES | F53: Expense | H53: 0
A54: 718 | B54: 718 | C54: Expense | D54: AMORTIZATION OF DEFERRED EXPENSES : AMORTIZATION OF DEFERRED EXPENSES | E54: 10206 AMORTIZATION OF DEFERRED EXPENSES : AMORTIZATION OF DEFERRED EXPENSES | F54: Expense | H54: 0 | I54: Depreciation Expense,Disposal Cost Account,Write Down Account,Write Off Account
A55: 363 | B55: 363 | C55: Other Current Asset | D55: ASSETS, WITHHOLDING TAX | E55: A44255 ASSETS, WITHHOLDING TAX | F55: Other Current Asset | H55: 0
...
