Workbook

Sheet PO with created By ASR
A1: External Id | B1: Voucher No | C1: Date | D1: Vendor raw | E1: Vendor without location | F1: Matched Vendor | G1: Branch | H1: Vch Type | I1: Created By | J1: Project | K1: Type of Expense | L1: Nature of Document | M1: Place of Supply | N1: Subsidiary | O1: Terms | P1: Approval Status | Q1: Department | R1: Line of business | S1: Subsidiary Location | T1: Nexus Override | U1: Nexus | V1: Currency | W1: Item raw | X1: Item Matched | Y1: Quantity Lookup | Z1: Rate Lookup | AA1: Order By (Other Refernence) raw | AB1: Order By (Other Refernence) Matched | AC1: HSN & SAC Code
A2: B/2025/PO/000001 | B2: B/2025/PO/000001 | C2: 45658 | D2: H P Ramareddy-Blr | E2: =_xlfn.TEXTBEFORE(D2,"-") -> H P Ramareddy | F2: 11014 H P Ramareddy | G2: B - Bangalore | H2: Purchase Order-Blr | I2: 1115173 Nagaraju R | K2: Indirect Expense | L2: Invoices for inward supply from unregistered person | N2: 6 | O2: 10 Days | P2: Pending Approval | T2: TRUE | U2: Nexus-Karnataka | V2: Indian Rupee | W2: Office Rent | X2: Rent Office | Y2: 1 | Z2: 245446 | AC2: CGST Input for KT (DT) 9%
A3: B/2025/PO/000002 | B3: B/2025/PO/000002 | C3: 45658 | D3: A Ramareddy (Rent)-Blr | E3: =_xlfn.TEXTBEFORE(D3,"-") -> A Ramareddy (Rent) | F3: 11009 A Ramareddy (Rent) | G3: B - Bangalore | H3: Purchase Order-Blr | I3: 1115173 Nagaraju R | K3: Indirect Expense | L3: Invoices for inward supply from unregistered person | N3: 6 | O3: 10 Days | P3: Pending Approval | T3: TRUE | U3: Nexus-Karnataka | V3: Indian Rupee | W3: Office Rent | X3: Rent Office | Y3: 1 | Z3: 245446 | AC3: CGST Input for KT (DT) 9%
A4: B/2025/PO/000003 | B4: B/2025/PO/000003 | C4: 45658 | D4: H P Ramareddy Utility-Blr | E4: =_xlfn.TEXTBEFORE(D4,"-") -> H P Ramareddy Utility | F4: 11015 H P Ramareddy Utility | G4: B - Bangalore | H4: Purchase Order-Blr | I4: 1115173 Nagaraju R | K4: Indirect Expense | L4: Invoices for inward supply from unregistered person | N4: 6 | O4: 10 Days | P4: Pending Approval | T4: TRUE | U4: Nexus-Karnataka | V4: Indian Rupee | W4: Water Charges | X4: Water Charges | Y4: 1 | Z4: 4000 | AC4: #N/A
A5: B/2025/PO/000004 | B5: B/2025/PO/000004 | C5: 45658 | D5: Renaissance Bengaluru Race Course Hotel (Dharampal Satyapal Ltd)-Blr | E5: =_xlfn.TEXTBEFORE(D5,"-") -> Renaissance Bengaluru Race Course Hotel (Dharampal Satyapal Ltd) | F5: 10403 Renaissance Bengaluru Race Course Hotel (Dharampal Satyapal Ltd) | G5: B - Bangalore | H5: Purchase Order-Blr | I5: 1138596 Yogesh A | J5: SB 22267 | K5: Direct Expense | L5: Invoices for inward supply from unregistered person | N5: 6 | O5: 90 Days | P5: Pending Approval | Q5: BU North | R5: Event Management | S5: Delhi | T5: TRUE | U5: Nexus-Karnataka | V5: Indian Rupee | W5: STAY CHARGES (DE) | X5: Stay Charges - Events | Y5: 1 | Z5: 279000 | AA5: Alok Khanna | AB5: 1137790 Alok Khanna | AC5: CGST Input for KT (DT) 9%
A6: B/2025/PO/000005 | B6: B/2025/PO/000005 | C6: 45658 | D6: H P Ramareddy Utility-Blr | E6: =_xlfn.TEXTBEFORE(D6,"-") -> H P Ramareddy Utility | F6: 11015 H P Ramareddy Utility | G6: B - Bangalore | H6: Purchase Order-Blr | I6: 1115173 Nagaraju R | K6: Indirect Expense | L6: Invoices for inward supply from unregistered person | N6: 6 | O6: 10 Days | P6: Pending Approval | T6: TRUE | U6: Nexus-Karnataka | V6: Indian Rupee | W6: Electricity Expenses | X6: #N/A | Y6: 1 | Z6: 19073 | AC6: #N/A
A7: B/2025/PO/000006 | B7: B/2025/PO/000006 | C7: 45658 | D7: Lynx Security & Detectives Services (P) Ltd-Blr | E7: =_xlfn.TEXTBEFORE(D7,"-") -> Lynx Security & Detectives Services (P) Ltd | F7: 11520 Lynx Security & Detectives Services (P) Ltd | G7: B - Bangalore | H7: Purchase Order-Blr | I7: 1115173 Nagaraju R | K7: Indirect Expense | L7: Invoices for inward supply from unregistered person | N7: 6 | O7: 10 Days | P7: Pending Approval | T7: TRUE | U7: Nexus-Karnataka | V7: Indian Rupee | W7: Security Charges | X7: Security Charges | Y7: 1 | Z7: 48991 | AA7: Anurama V | AB7: 1131024 Anurama V | AC7: CGST Input for KT (DT) 9%
A8: B/2025/PO/000007 | B8: B/2025/PO/000007 | C8: 45658 | D8: Mayur Enterprises-Blr | E8: =_xlfn.TEXTBEFORE(D8,"-") -> Mayur Enterprises | F8: 11521 Mayur Enterprises | G8: B - Bangalore | H8: Purchase Order-Blr | I8: 1115173 Nagaraju R | K8: Indirect Expense | L8: Invoices for inward supply from unregistered person | N8: 6 | O8: 10 Days | P8: Pending Approval | T8: TRUE | U8: Nexus-Karnataka | V8: Indian Rupee | W8: Water Charges | X8: Water Charges | Y8: 1 | Z8: 1610 | AC8: Ineligible CGST Input-Gen
A9: B/2025/PO/000008 | B9: B/2025/PO/000008 | C9: 45658 | D9: K Vishwanath Gouda Rent-Blr | E9: =_xlfn.TEXTBEFORE(D9,"-") -> K Vishwanath Gouda Rent | F9: 11016 K Vishwanath Gouda Rent | G9: B - Bangalore | H9: Purchase Order-Blr | I9: 1115173 Nagaraju R | K9: Indirect Expense | L9: Invoices for inward supply from unregistered person | N9: 6 | O9: 10 Days | P9: Pending Approval | T9: TRUE | U9: Nexus-Karnataka | V9: Indian Rupee | W9: Rent - Storage Room | X9: Rent Storage Room | Y9: 1 | Z9: 27500 | AC9: #N/A
A10: B/2025/PO/000009 | B10: B/2025/PO/000009 | C10: 45658 | D10: K-Corp-Blr | E10: =_xlfn.TEXTBEFORE(D10,"-") -> K | F10: #N/A | G10: B - Bangalore | H10: Purchase Order-Blr | I10: 1115173 Nagaraju R | K10: Indirect Expense | L10: Invoices for inward supply from unregistered person | N10: 6 | O10: 90 Days | P10: Pending Approval | T10: TRUE | U10: Nexus-Karnataka | V10: Indian Rupee | W10: Computer Hire Charges | X10: Computer Hire Charges | Y10: 1 | Z10: 3500 | AC10: CGST Input for KT (DT) 9%
A11: B/2025/PO/000010 | B11: B/2025/PO/000010 | C11: 45658 | D11: Aaa Rental Llp-Mum | E11: =_xlfn.TEXTBEFORE(D11,"-") -> Aaa Rental Llp | F11: 11626 Aaa Rental Llp | G11: B - Bangalore | H11: Purchase Order-Blr | I11: 1115173 Nagaraju R | K11: Indirect Expense | L11: Invoices for inward supply from unregistered person | N11: 6 | O11: 45 Days | P11: Pending Approval | T11: TRUE | U11: Nexus-Karnataka | V11: Indian Rupee | W11: Computer Hire Charges | X11: Computer Hire Charges | Y11: 1 | Z11: 13500 | AA11: Tijo Joseph | AB11: 1128119 Tijo Joseph | AC11: CGST Input for KT (DT) 9%
A12: B/2025/PO/000011 | B12: B/2025/PO/000011 | C12: 45658 | D12: Bharti Airtel Ltd.-Del | E12: =_xlfn.TEXTBEFORE(D12,"-") -> Bharti Airtel Ltd. | F12: #N/A | G12: B - Bangalore | H12: Purchase Order-Blr | I12: 1115173 Nagaraju R | K12: Indirect Expense | L12: Invoices for inward supply from unregistered person | N12: 6 | O12: Immediate | P12: Pending Approval | T12: TRUE | U12: Nexus-Karnataka | V12: Indian Rupee | W12: Internet Expenses | X12: Internet Expenses - Events | Y12: 1 | Z12: 1498 | AA12: Tijo Joseph | AB12: 1128119 Tijo Joseph | AC12: CGST Input for KT (DT) 9%
A13: C/2025/PO/000001 | B13: C/2025/PO/000001 | C13: 45658 | D13: Elsie Mathew-Che | E13: =_xlfn.TEXTBEFORE(D13,"-") -> Elsie Mathew | F13: 11012 Elsie Mathew | G13: C - Chennai | H13: Purchase Order-Che | I13: 1115173 Nagaraju R | K13: Indirect Expense | L13: Invoices for inward supply from unregistered person | N13: 6 | O13: 10 Days | P13: Pending Approval | T13: TRUE | U13: Nexus-Tamil Nadu | V13: Indian Rupee | W13: Office Rent | X13: Rent Office | Y13: 1 | Z13: 73500 | AA13: Aravind Kumar S | AB13: 1044838 Aravind Kumar.S | AC13: #N/A
A14: C/2025/PO/000002 | B14: C/2025/PO/000002 | C14: 45658 | D14: Race View Tower Association-Che | E14: =_xlfn.TEXTBEFORE(D14,"-") -> Race View Tower Association | F14: 11525 Race View Tower Association | G14: C - Chennai | H14: Purchase Order-Che | I14: 1115173 Nagaraju R | K14: Indirect Expense | L14: Invoices for inward supply from unregistered person | N14: 6 | O14: 10 Days | P14: Pending Approval | T14: TRUE | U14: Nexus-Tamil Nadu | V14: Indian Rupee | W14: Office Maintainance Expenses | X14: #N/A | Y14: 1 | Z14: 4000 | AA14: Aravind Kumar S | AB14: 1044838 Aravind Kumar.S | AC14: #N/A
A15: C/2025/PO/000003 | B15: C/2025/PO/000003 | C15: 45658 | D15: Unicare Hospitality Services Pvt Ltd-Che | E15: =_xlfn.TEXTBEFORE(D15,"-") -> Unicare Hospitality Services Pvt Ltd | F15: 12571 Unicare Hospitality Services Pvt Ltd | G15: C - Chennai | H15: Purchase Order-Che | I15: 1115173 Nagaraju R | K15: Indirect Expense | L15: Invoices for inward supply from unregistered person | N15: 6 | O15: 45 Days | P15: Pending Approval | T15: TRUE | U15: Nexus-Tamil Nadu | V15: Indian Rupee | W15: Security Charges | X15: Security Charges | Y15: 1 | Z15: 28273 | AA15: Aravind Kumar S | AB15: 1044838 Aravind Kumar.S | AC15: CGST Input for TN (DT) 9%
A16: B/2025/PO/000012 | B16: B/2025/PO/000012 | C16: 45659 | D16: Siva Sankar Cabs-Blr | E16: =_xlfn.TEXTBEFORE(D16,"-") -> Siva Sankar Cabs | F16: 10089 Siva Sankar Cabs | G16: B - Bangalore | H16: Purchase Order-Blr | I16: 1115173 Nagaraju R | J16: SB 22270 | K16: Direct Expense | L16: Invoices for inward supply from unregistered person | N16: 6 | O16: 30 Days | P16: Pending Approval | Q16: BU South | R16: Event Management | S16: Bangalore | T16: TRUE | U16: Nexus-Karnataka | V16: Indian Rupee | W16: CAR HIRE CHARGES - EVENTS (DE) | X16: CarHireCharges | Y16: 1 | Z16: 9400 | AA16: Thirtha Patil | AB16: 1138809 Thirtha Patil | AC16: #N/A
A17: B/2025/PO/000013 | B17: B/2025/PO/000013 | C17: 45659 | D17: Arun Kumar M -CR | E17: =_xlfn.TEXTBEFORE(D17,"-") -> Arun Kumar M | F17: #N/A | G17: B - Bangalore | H17: Purchase Order-Blr | I17: 1115173 Nagaraju R | J17: SB 22190 | K17: Direct Expense | L17: Invoices for inward supply from unregistered person | N17: 6 | O17: Immediate | P17: Pending Approval | Q17: BU South | R17: Event Management | S17: Bangalore | T17: TRUE | U17: Nexus-Karnataka | V17: Indian Rupee | W17: CONVEYANCE - EVENTS (DE) | X17: Conveyance | Y17: 1 | Z17: 5599 | AA17: Amrita Sawhney | AB17: 1122672 Amrita Sawhney | AC17: #N/A
A18: B/2025/PO/000014 | B18: B/2025/PO/000014 | C18: 45659 | D18: Sky Office Stationers-Blr | E18: =_xlfn.TEXTBEFORE(D18,"-") -> Sky Office Stationers | F18: 12417 Sky Office Stationers | G18: B - Bangalore | H18: Purchase Order-Blr | I18: EBP BlrChe | K18: Indirect Expense | L18: Invoices for inward supply from unregistered person | N18: 6 | O18: 45 Days | P18: Pending Approval | T18: TRUE | U18: Nexus-Karnataka | V18: Indian Rupee | W18: Staff Welfare | X18: Staff Welfare - Others | Y18: 1 | Z18: 2846 | AA18: Anurama V | AB18: 1131024 Anurama V | AC18: Ineligible CGST Input-Gen
A19: C/2025/PO/000004 | B19: C/2025/PO/000004 | C19: 45659 | D19: The Westin Chennai Velachery (MFAR Hotels and Resorts Pvt Ltd)-Che | E19: =_xlfn.TEXTBEFORE(D19,"-") -> The Westin Chennai Velachery (MFAR Hotels and Resorts Pvt Ltd) | F19: 10468 The Westin Chennai Velachery (MFAR Hotels and Resorts Pvt Ltd) | G19: C - Chennai | H19: Purchase Order-Che | I19: 1138596 Yogesh A | J19: SB 22254 | K19: Direct Expense | L19: Invoices for inward supply from unregistered person | N19: 6 | O19: Immediate | P19: Pending Approval | Q19: BU North | R19: Event Management | S19: Delhi | T19: TRUE | U19: Nexus-Tamil Nadu | V19: Indian Rupee | W19: EVENT EXPENSES-GIVE AWAYS | X19: Event Expenses - Giveaways | Y19: 1 | Z19: 69600 | AA19: Harshit Jain | AB19: 1044966 Harshit Jain | AC19: CGST Input for TN (DT) 9%
A20: D/2025/PO/000001 | B20: D/2025/PO/000001 | C20: 45659 | D20: Jarvas Smart Solutions Pvt Ltd-Del | E20: =_xlfn.TEXTBEFORE(D20,"-") -> Jarvas Smart Solutions Pvt Ltd | F20: 12882 Jarvas Smart Solutions Pvt Ltd | G20: D - Delhi | H20: Purchase Order-Del | I20: 1138596 Yogesh A | J20: SB 22159 | K20: Direct Expense | L20: Invoices for inward supply from unregistered person | N20: 6 | O20: 45 Days | P20: Pending Approval | Q20: BU North | R20: Event Management | S20: Delhi | T20: TRUE | U20: Nexus-Delhi | V20: Indian Rupee | W20: STAGE & SET EXPENSES (DE) | X20: Stage & Set Expenses - Events | Y20: 1 | Z20: 3787500 | AA20: Ravi Kiroula | AB20: 1128186 Ravi Kiroula | AC20: IGST Input for DL (DT) 18%
A21: D/2025/PO/000002 | B21: D/2025/PO/000002 | C21: 45659 | D21: Rishi Computers-Del | E21: =_xlfn.TEXTBEFORE(D21,"-") -> Rishi Computers | F21: 12343 Rishi Computers | G21: D - Delhi | H21: Purchase Order-Del | I21: 1135026 Gaurav Khurana | K21: Indirect Expense | L21: Invoices for inward supply from unregistered person | N21: 6 | O21: 45 Days | P21: Pending Approval | T21: TRUE | U21: Nexus-Delhi | V21: Indian Rupee | W21: Laptop Dell(P) | X21: #N/A | Y21: 6 | Z21: 81000 | AA21: Abhishek | AB21: 1140231 Abhishek Jadhav | AC21: CGST Input for DL (DT) 9%
A22: D/2025/PO/000003 | B22: D/2025/PO/000003 | C22: 45659 | D22: Rishi Computers-Del | E22: =_xlfn.TEXTBEFORE(D22,"-") -> Rishi Computers | F22: 12343 Rishi Computers | G22: D - Delhi | H22: Purchase Order-Del | I22: 1135026 Gaurav Khurana | K22: Indirect Expense | L22: Invoices for inward supply from unregistered person | N22: 6 | O22: 45 Days | P22: Pending Approval | T22: TRUE | U22: Nexus-Delhi | V22: Indian Rupee | W22: Computer | X22: #N/A | Y22: 2 | Z22: 315000 | AA22: Abhishek | AB22: 1140231 Abhishek Jadhav | AC22: CGST Input for DL (DT) 9%
A23: D/2025/PO/000004 | B23: D/2025/PO/000004 | C23: 45659 | D23: Saksham Signs Pvt Ltd-Del | E23: =_xlfn.TEXTBEFORE(D23,"-") -> Saksham Signs Pvt Ltd | F23: 12886 Saksham Signs Pvt Ltd | G23: D - Delhi | H23: Purchase Order-Del | I23: 1138596 Yogesh A | J23: SB 22159 | K23: Direct Expense | L23: Invoices for inward supply from unregistered person | N23: 6 | O23: 45 Days | P23: Pending Approval | Q23: BU North | R23: Event Management | S23: Delhi | T23: TRUE | U23: Nexus-Delhi | V23: Indian Rupee | W23: STAGE & SET EXPENSES (DE) | X23: Stage & Set Expenses - Events | Y23: 1 | Z23: 491000 | AA23: Ravi Kiroula | AB23: 1128186 Ravi Kiroula | AC23: IGST Input for DL (DT) 18%
A24: D/2025/PO/000005 | B24: D/2025/PO/000005 | C24: 45659 | D24: Gurdeep Kaur-Del | E24: =_xlfn.TEXTBEFORE(D24,"-") -> Gurdeep Kaur | F24: 11103 Gurdeep Kaur | G24: D - Delhi | H24: Purchase Order-Del | I24: 1138596 Yogesh A | K24: Indirect Expense | L24: Invoices for inward supply from unregistered person | N24: 6 | O24: 90 Days | P24: Pending Approval | T24: TRUE | U24: Nexus-Delhi | V24: Indian Rupee | W24: Computer Hire Charges | X24: Computer Hire Charges | Y24: 1 | Z24: 28000 | AA24: Gurpreet Singh | AB24: 1044881 Gurpreet Singh Khani | AC24: CGST Input for DL (DT) 9%
A25: D/2025/PO/000006 | B25: D/2025/PO/000006 | C25: 45659 | D25: Gurdeep Kaur-Del | E25: =_xlfn.TEXTBEFORE(D25,"-") -> Gurdeep Kaur | F25: 11103 Gurdeep Kaur | G25: D - Delhi | H25: Purchase Order-Del | I25: 1138596 Yogesh A | K25: Indirect Expense | L25: Invoices for inward supply from unregistered person | N25: 6 | O25: 90 Days | P25: Pending Approval | T25: TRUE | U25: Nexus-Delhi | V25: Indian Rupee | W25: Computer Hire Charges | X25: Computer Hire Charges | Y25: 1 | Z25: 22000 | AA25: Gurpreet Singh | AB25: 1044881 Gurpreet Singh Khani | AC25: CGST Input for DL (DT) 9%
A26: D/2025/PO/000007 | B26: D/2025/PO/000007 | C26: 45659 | D26: Aaa Rental Llp-Mum | E26: =_xlfn.TEXTBEFORE(D26,"-") -> Aaa Rental Llp | F26: 11626 Aaa Rental Llp | G26: D - Delhi | H26: Purchase Order-Del | I26: 1138596 Yogesh A | K26: Indirect Expense | L26: Invoices for inward supply from unregistered person | N26: 6 | O26: 45 Days | P26: Pending Approval | T26: TRUE | U26: Nexus-Delhi | V26: Indian Rupee | W26: Computer Hire Charges | X26: Computer Hire Charges | Y26: 1 | Z26: 22000 | AA26: Gurpreet | AB26: 1044881 Gurpreet Singh Khani | AC26: CGST Input for DL (DT) 9%
A27: D/2025/PO/000008 | B27: D/2025/PO/000008 | C27: 45659 | D27: Aaa Rental Llp-Mum | E27: =_xlfn.TEXTBEFORE(D27,"-") -> Aaa Rental Llp | F27: 11626 Aaa Rental Llp | G27: D - Delhi | H27: Purchase Order-Del | I27: 1138596 Yogesh A | K27: Indirect Expense | L27: Invoices for inward supply from unregistered person | N27: 6 | O27: 45 Days | P27: Pending Approval | T27: TRUE | U27: Nexus-Delhi | V27: Indian Rupee | W27: Computer Hire Charges | X27: Computer Hire Charges | Y27: 2 | Z27: 21000 | AA27: Gurpreet | AB27: 1044881 Gurpreet Singh Khani | AC27: CGST Input for DL (DT) 9%
A28: D/2025/PO/000009 | B28: D/2025/PO/000009 | C28: 45659 | D28: Aaa Rental Llp-Mum | E28: =_xlfn.TEXTBEFORE(D28,"-") -> Aaa Rental Llp | F28: 11626 Aaa Rental Llp | G28: D - Delhi | H28: Purchase Order-Del | I28: 1138596 Yogesh A | K28: Indirect Expense | L28: Invoices for inward supply from unregistered person | N28: 6 | O28: 45 Days | P28: Pending Approval | T28: TRUE | U28: Nexus-Delhi | V28: Indian Rupee | W28: Computer Hire Charges | X28: Computer Hire Charges | Y28: 1 | Z28: 19000 | AA28: Gurpreet | AB28: 1044881 Gurpreet Singh Khani | AC28: CGST Input for DL (DT) 9%
A29: A/2025/PO/000001 | B29: A/2025/PO/000001 | C29: 45659 | D29: Ekatra Collective Pvt Ltd-Mum | E29: =_xlfn.TEXTBEFORE(D29,"-") -> Ekatra Collective Pvt Ltd | F29: 12858 Ekatra Collective Pvt Ltd | G29: A - Mumbai | H29: Purchase Order-Mum | I29: 1138574 Swapnil Bangal | J29: SB 22256 | K29: Direct Expense | L29: Invoices for inward supply from unregistered person | N29: 6 | O29: 45 Days | P29: Pending Approval | Q29: BU South | R29: Event Management | S29: Chennai | T29: FALSE | U29: Nexus-Maharashtra | V29: Indian Rupee | W29: EVENT EXPENSES-GIVE AWAYS | X29: Event Expenses - Giveaways | Y29: 1 | Z29: 13259.16 | AA29: Clinton Jesuraja | AB29: 1044969 Clinton J | AC29: IGST Input for MH 12%
A30: A/2025/PO/000002 | B30: A/2025/PO/000002 | C30: 45659 | D30: Noaman Digital Partnership Firm-Mum | E30: =_xlfn.TEXTBEFORE(D30,"-") -> Noaman Digital Partnership Firm | F30: #N/A | G30: A - Mumbai | H30: Purchase Order-Mum | I30: 1138574 Swapnil Bangal | J30: SB 22123 | K30: Direct Expense | L30: Invoices for inward supply from unregistered person | N30: 6 | O30: 45 Days | P30: Pending Approval | Q30: BU West | R30: Event Management | S30: Mumbai | T30: FALSE | U30: Nexus-Maharashtra | V30: Indian Rupee | W30: PRINTING & STATIONERY - EVENTS | X30: Printing & Stationery - Events | Y30: 1 | Z30: 11793 | AA30: Aftab Shaikh | AB30: 1133492 Aftab Mobin Shaikh | AC30: CGST Input for MH (DT) 9%
A31: A/2025/PO/000003 | B31: A/2025/PO/000003 | C31: 45659 | D31: Turbonet Systems Pvt Ltd-Mum | E31: =_xlfn.TEXTBEFORE(D31,"-") -> Turbonet Systems Pvt Ltd | F31: 12560 Turbonet Systems Pvt Ltd | G31: A - Mumbai | H31: Purchase Order-Mum | I31: 1138574 Swapnil Bangal | J31: SB 22212 | K31: Direct Expense | L31: Invoices for inward supply from unregistered person | N31: 6 | O31: 45 Days | P31: Pending Approval | Q31: BU West | R31: Event Management | S31: Mumbai | T31: FALSE | U31: Nexus-Maharashtra | V31: Indian Rupee | W31: Courier Charges - Events | X31: Courier Charges - Events | Y31: 1 | Z31: 7000 | AA31: Neetuprakash Poojary | AB31: 1044835 Neetu Prakash Poojary | AC31: CGST Input for MH (DT) 9%
A32: A/2025/PO/000004 | B32: A/2025/PO/000004 | C32: 45659 | D32: Jaguar Security Services Pvt Ltd-Mum | E32: =_xlfn.TEXTBEFORE(D32,"-") -> Jaguar Security Services Pvt Ltd | F32: 12046 Jaguar Security Services Pvt Ltd | G32: A - Mumbai | H32: Purchase Order-Mum | I32: 1138574 Swapnil Bangal | J32: SB 21718 | K32: Direct Expense | L32: Invoices for inward supply from unregistered person | N32: 6 | O32: 45 Days | P32: Pending Approval | T32: FALSE | U32: Nexus-Maharashtra | V32: Indian Rupee | W32: SECURITY CHARGES - EVENTS | X32: Security Charges - Events | Y32: 1 | Z32: 165000 | AA32: Hari Bailwal | AB32: 1044898 Hari Bailwal | AC32: IGST Input for MH (DT) 18%
A33: C/2025/PO/000005 | B33: C/2025/PO/000005 | C33: 45660 | D33: Tata Teleservices Ltd-Blr | E33: =_xlfn.TEXTBEFORE(D33,"-") -> Tata Teleservices Ltd | F33: 10964 Tata Teleservices Ltd | G33: C - Chennai | H33: Purchase Order-Che | I33: 1115173 Nagaraju R | K33: Indirect Expense | L33: Invoices for inward supply from unregistered person | N33: 6 | O33: 15 Days | P33: Pending Approval | T33: TRUE | U33: Nexus-Tamil Nadu | V33: Indian Rupee | W33: Internet Expenses | X33: Internet Expenses - Events | Y33: 1 | Z33: 62500 | AA33: Amir Merchant | AB33: 1044800 Amir Merchant | AC33: CGST Input for TN (DT) 9%
A34: D/2025/PO/000010 | B34: D/2025/PO/000010 | C34: 45660 | D34: Goldline Security Systems-Del | E34: =_xlfn.TEXTBEFORE(D34,"-") -> Goldline Security Systems | F34: 12880 Goldline Security Systems | G34: D - Delhi | H34: Purchase Order-Del | I34: 1135026 Gaurav Khurana | K34: Indirect Expense | L34: Invoices for inward supply from unregistered person | N34: 6 | O34: 45 Days | P34: Pending Approval | T34: TRUE | U34: Nexus-Delhi | V34: Indian Rupee | W34: Fire Alarm (Office Equipment) | X34: #N/A | Y34: 1 | Z34: 116703 | AA34: Pankaj | AB34: 1044903 Pankaj Kumar Mishra | AC34: CGST Input for DL (DT) 9%
A35: D/2025/PO/000010 | B35: D/2025/PO/000010 | C35: 45660 | D35: Goldline Security Systems-Del | E35: =_xlfn.TEXTBEFORE(D35,"-") -> Goldline Security Systems | F35: 12880 Goldline Security Systems | G35: D - Delhi | H35: Purchase Order-Del | I35: 1135026 Gaurav Khurana | K35: Indirect Expense | L35: Invoices for inward supply from unregistered person | N35: 6 | O35: 45 Days | P35: Pending Approval | T35: TRUE | U35: Nexus-Delhi | V35: Indian Rupee | W35: Fire Alarm (Office Equipment) | X35: #N/A | Y35: 1 | Z35: 116703 | AA35: Pankaj | AB35: 1044903 Pankaj Kumar Mishra | AC35: CGST Input for DL (DT) 9%
A36: D/2025/PO/000011 | B36: D/2025/PO/000011 | C36: 45660 | D36: Goldline Security Systems-Del | E36: =_xlfn.TEXTBEFORE(D36,"-") -> Goldline Security Systems | F36: 12880 Goldline Security Systems | G36: D - Delhi | H36: Purchase Order-Del | I36: 1135026 Gaurav Khurana | K36: Indirect Expense | L36: Invoices for inward supply from unregistered person | N36: 6 | O36: 45 Days | P36: Pending Approval | T36: TRUE | U36: Nexus-Delhi | V36: Indian Rupee | W36: Office Maintainance Expenses | X36: #N/A | Y36: 1 | Z36: 68802 | AA36: Pankaj | AB36: 1044903 Pankaj Kumar Mishra | AC36: CGST Input for DL (DT) 9%
A37: D/2025/PO/000012 | B37: D/2025/PO/000012 | C37: 45660 | D37: Wanderers Adventure Sports Pvt Ltd-Del | E37: =_xlfn.TEXTBEFORE(D37,"-") -> Wanderers Adventure Sports Pvt Ltd | F37: 10103 Wanderers Adventure Sports Pvt Ltd | G37: D - Delhi | H37: Purchase Order-Del | I37: 1044835 Neetu Prakash Poojary | J37: SB 22159 | K37: Direct Expense | L37: Invoices for inward supply from unregistered person | N37: 6 | O37: 90 Days | P37: Pending Approval | Q37: BU North | R37: Event Management | S37: Delhi | T37: TRUE | U37: Nexus-Delhi | V37: Indian Rupee | W37: EVENT EXPENSES /OTHERS | X37: Event Expenses - Others | Y37: 1 | Z37: 138013 | AA37: SONIA | AB37: 1114836 Sonia Thakur | AC37: CGST Input for DL (DT) 9%
A38: D/2025/PO/000013 | B38: D/2025/PO/000013 | C38: 45660 | D38: Studio Merchandise Pvt Ltd-Del | E38: =_xlfn.TEXTBEFORE(D38,"-") -> Studio Merchandise Pvt Ltd | F38: 12464 Studio Merchandise Pvt Ltd | G38: D - Delhi | H38: Purchase Order-Del | I38: 1138596 Yogesh A | J38: SB 22120 | K38: Direct Expense | L38: Invoices for inward supply from unregistered person | N38: 6 | O38: 45 Days | P38: Pending Approval | Q38: BU North | R38: Event Management | S38: Delhi | T38: TRUE | U38: Nexus-Delhi | V38: Indian Rupee | W38: EVENT EXPENSES-GIVE AWAYS | X38: Event Expenses - Giveaways | Y38: 1 | Z38: 147300 | AA38: Varun Sondhi | AB38: 1129995 Varun Sodhi | AC38: CGST Input for DL (DT) 9%
A39: A/2025/PO/000005 | B39: A/2025/PO/000005 | C39: 45660 | D39: Fairfield By Marriott Mumbai (Associated Hospitality Pvt Ltd)-Mum | E39: =_xlfn.TEXTBEFORE(D39,"-") -> Fairfield By Marriott Mumbai (Associated Hospitality Pvt Ltd) | F39: 11911 Fairfield By Marriott Mumbai (Associated Hospitality Pvt Ltd) | G39: A - Mumbai | H39: Purchase Order-Mum | I39: 1138596 Yogesh A | J39: SB 22120 | K39: Direct Expense | L39: Invoices for inward supply from unregistered person | N39: 6 | O39: Immediate | P39: Pending Approval | Q39: BU North | R39: Event Management | S39: Delhi | T39: FALSE | U39: Nexus-Maharashtra | V39: Indian Rupee | W39: STAY CHARGES (DE) | X39: Stay Charges - Events | Y39: 1 | Z39: 41000 | AA39: Alok Khanna | AB39: 1137790 Alok Khanna | AC39: CGST Input for MH (DT) 9%
A40: A/2025/PO/000006 | B40: A/2025/PO/000006 | C40: 45660 | D40: Black Hat Talent Solutions & Consulting Pvt Ltd-Mum | E40: =_xlfn.TEXTBEFORE(D40,"-") -> Black Hat Talent Solutions & Consulting Pvt Ltd | F40: 10572 Black Hat Talent Solutions & Consulting Pvt Ltd | G40: A - Mumbai | H40: Purchase Order-Mum | I40: 1044835 Neetu Prakash Poojary | J40: SB 22196 | K40: Direct Expense | L40: Invoices for inward supply from unregistered person | N40: 6 | O40: 90 Days | P40: Pending Approval | Q40: BU North | R40: Event Management | S40: Delhi | T40: FALSE | U40: Nexus-Maharashtra | V40: Indian Rupee | W40: PERFORMER EXPENSES | X40: Performer Expenses | Y40: 1 | Z40: 540000 | AA40: SHRUTI GUPTA | AB40: 1135015 Shruti Gupta | AC40: CGST Input for MH (DT) 9%
...

Sheet PO Final
A1: Date | B1: Order | C1: Particulars | D1: Quantity | E1: Unit Price | F1: Branch | G1: Vendor | J1: Branch | K1: Created By | L1: Project | M1: Type of Expense | N1: Nature of Document | O1: Place of Supply | P1: Subsidiary | Q1: Terms | R1: Approval Status | S1: Department | T1: Line of business | U1: Subsidiary Location | V1: Nexus Override | W1: Nexus
B2: B/2025/PO/000001 | C2: Office Rent | D2: 1 | E2: 245446 | F2: 245446 | G2: =VLOOKUP(B2,'PO with created By ASR'!A:C,3,FALSE) -> 45658 | J2: =VLOOKUP(B2,'PO with created By ASR'!A:G,4,FALSE) -> H P Ramareddy-Blr | K2: =VLOOKUP(B2,'PO with created By ASR'!A:I,6,FALSE) -> 11014 H P Ramareddy | L2: =VLOOKUP(B2,'PO with created By ASR'!A:J,7,FALSE) -> B - Bangalore | M2: =VLOOKUP(B2,'PO with created By ASR'!A:K,8,FALSE) -> Purchase Order-Blr | N2: Invoices for inward supply from unregistered person | P2: 6
B3: B/2025/PO/000002 | C3: Office Rent | D3: 1 | E3: 245446 | F3: 245446 | G3: =VLOOKUP(B3,'PO with created By ASR'!A:C,3,FALSE) -> 45658 | J3: =VLOOKUP(B3,'PO with created By ASR'!A:G,4,FALSE) -> A Ramareddy (Rent)-Blr | K3: =VLOOKUP(B3,'PO with created By ASR'!A:I,6,FALSE) -> 11009 A Ramareddy (Rent) | L3: =VLOOKUP(B3,'PO with created By ASR'!A:J,7,FALSE) -> B - Bangalore | M3: =VLOOKUP(B3,'PO with created By ASR'!A:K,8,FALSE) -> Purchase Order-Blr | N3: Invoices for inward supply from unregistered person | P3: 6
B4: B/2025/PO/000003 | C4: Water Charges | D4: 1 | E4: 4000 | F4: 4000 | G4: =VLOOKUP(B4,'PO with created By ASR'!A:C,3,FALSE) -> 45658 | J4: =VLOOKUP(B4,'PO with created By ASR'!A:G,4,FALSE) -> H P Ramareddy Utility-Blr | K4: =VLOOKUP(B4,'PO with created By ASR'!A:I,6,FALSE) -> 11015 H P Ramareddy Utility | L4: =VLOOKUP(B4,'PO with created By ASR'!A:J,7,FALSE) -> B - Bangalore | M4: =VLOOKUP(B4,'PO with created By ASR'!A:K,8,FALSE) -> Purchase Order-Blr | N4: Invoices for inward supply from unregistered person | P4: 6
B5: B/2025/PO/000004 | C5: STAY CHARGES (DE) | D5: 1 | E5: 279000 | F5: 279000 | G5: =VLOOKUP(B5,'PO with created By ASR'!A:C,3,FALSE) -> 45658 | J5: =VLOOKUP(B5,'PO with created By ASR'!A:G,4,FALSE) -> Renaissance Bengaluru Race Course Hotel (Dharampal Satyapal Ltd)-Blr | K5: =VLOOKUP(B5,'PO with created By ASR'!A:I,6,FALSE) -> 10403 Renaissance Bengaluru Race Course Hotel (Dharampal Satyapal Ltd) | L5: =VLOOKUP(B5,'PO with created By ASR'!A:J,7,FALSE) -> B - Bangalore | M5: =VLOOKUP(B5,'PO with created By ASR'!A:K,8,FALSE) -> Purchase Order-Blr | N5: Invoices for inward supply from unregistered person | P5: 6
B6: B/2025/PO/000005 | C6: Electricity Expenses | D6: 1 | E6: 19073 | F6: 19073 | G6: =VLOOKUP(B6,'PO with created By ASR'!A:C,3,FALSE) -> 45658 | J6: =VLOOKUP(B6,'PO with created By ASR'!A:G,4,FALSE) -> H P Ramareddy Utility-Blr | K6: =VLOOKUP(B6,'PO with created By ASR'!A:I,6,FALSE) -> 11015 H P Ramareddy Utility | L6: =VLOOKUP(B6,'PO with created By ASR'!A:J,7,FALSE) -> B - Bangalore | M6: =VLOOKUP(B6,'PO with created By ASR'!A:K,8,FALSE) -> Purchase Order-Blr | N6: Invoices for inward supply from unregistered person | P6: 6
B7: B/2025/PO/000006 | C7: Security Charges | D7: 1 | E7: 48991 | F7: 48991 | G7: =VLOOKUP(B7,'PO with created By ASR'!A:C,3,FALSE) -> 45658 | J7: =VLOOKUP(B7,'PO with created By ASR'!A:G,4,FALSE) -> Lynx Security & Detectives Services (P) Ltd-Blr | K7: =VLOOKUP(B7,'PO with created By ASR'!A:I,6,FALSE) -> 11520 Lynx Security & Detectives Services (P) Ltd | L7: =VLOOKUP(B7,'PO with created By ASR'!A:J,7,FALSE) -> B - Bangalore | M7: =VLOOKUP(B7,'PO with created By ASR'!A:K,8,FALSE) -> Purchase Order-Blr | N7: Invoices for inward supply from unregistered person | P7: 6
B8: B/2025/PO/000006 | C8: Office Maintainance Expenses | D8: 1 | E8: 23151 | F8: 23151 | G8: =VLOOKUP(B8,'PO with created By ASR'!A:C,3,FALSE) -> 45658 | J8: =VLOOKUP(B8,'PO with created By ASR'!A:G,4,FALSE) -> Lynx Security & Detectives Services (P) Ltd-Blr | K8: =VLOOKUP(B8,'PO with created By ASR'!A:I,6,FALSE) -> 11520 Lynx Security & Detectives Services (P) Ltd | L8: =VLOOKUP(B8,'PO with created By ASR'!A:J,7,FALSE) -> B - Bangalore | M8: =VLOOKUP(B8,'PO with created By ASR'!A:K,8,FALSE) -> Purchase Order-Blr | N8: Invoices for inward supply from unregistered person | P8: 6
B9: B/2025/PO/000007 | C9: Water Charges | D9: 1 | E9: 1610 | F9: 1610 | G9: =VLOOKUP(B9,'PO with created By ASR'!A:C,3,FALSE) -> 45658 | J9: =VLOOKUP(B9,'PO with created By ASR'!A:G,4,FALSE) -> Mayur Enterprises-Blr | K9: =VLOOKUP(B9,'PO with created By ASR'!A:I,6,FALSE) -> 11521 Mayur Enterprises | L9: =VLOOKUP(B9,'PO with created By ASR'!A:J,7,FALSE) -> B - Bangalore | M9: =VLOOKUP(B9,'PO with created By ASR'!A:K,8,FALSE) -> Purchase Order-Blr | N9: Invoices for inward supply from unregistered person | P9: 6
B10: B/2025/PO/000007 | C10: Ineligible CGST Input-Gen | D10: 1 | E10: 97 | F10: 97 | G10: =VLOOKUP(B10,'PO with created By ASR'!A:C,3,FALSE) -> 45658 | J10: =VLOOKUP(B10,'PO with created By ASR'!A:G,4,FALSE) -> Mayur Enterprises-Blr | K10: =VLOOKUP(B10,'PO with created By ASR'!A:I,6,FALSE) -> 11521 Mayur Enterprises | L10: =VLOOKUP(B10,'PO with created By ASR'!A:J,7,FALSE) -> B - Bangalore | M10: =VLOOKUP(B10,'PO with created By ASR'!A:K,8,FALSE) -> Purchase Order-Blr | N10: Invoices for inward supply from unregistered person | P10: 6
B11: B/2025/PO/000007 | C11: Ineligible SGST Input-Gen | D11: 1 | E11: 97 | F11: 97 | G11: =VLOOKUP(B11,'PO with created By ASR'!A:C,3,FALSE) -> 45658 | J11: =VLOOKUP(B11,'PO with created By ASR'!A:G,4,FALSE) -> Mayur Enterprises-Blr | K11: =VLOOKUP(B11,'PO with created By ASR'!A:I,6,FALSE) -> 11521 Mayur Enterprises | L11: =VLOOKUP(B11,'PO with created By ASR'!A:J,7,FALSE) -> B - Bangalore | M11: =VLOOKUP(B11,'PO with created By ASR'!A:K,8,FALSE) -> Purchase Order-Blr | N11: Invoices for inward supply from unregistered person | P11: 6
B12: B/2025/PO/000008 | C12: Rent - Storage Room | D12: 1 | E12: 27500 | F12: 27500 | G12: =VLOOKUP(B12,'PO with created By ASR'!A:C,3,FALSE) -> 45658 | J12: =VLOOKUP(B12,'PO with created By ASR'!A:G,4,FALSE) -> K Vishwanath Gouda Rent-Blr | K12: =VLOOKUP(B12,'PO with created By ASR'!A:I,6,FALSE) -> 11016 K Vishwanath Gouda Rent | L12: =VLOOKUP(B12,'PO with created By ASR'!A:J,7,FALSE) -> B - Bangalore | M12: =VLOOKUP(B12,'PO with created By ASR'!A:K,8,FALSE) -> Purchase Order-Blr | N12: Invoices for inward supply from unregistered person | P12: 6
B13: B/2025/PO/000009 | C13: Computer Hire Charges | D13: 1 | E13: 3500 | F13: 3500 | G13: =VLOOKUP(B13,'PO with created By ASR'!A:C,3,FALSE) -> 45658 | J13: =VLOOKUP(B13,'PO with created By ASR'!A:G,4,FALSE) -> K-Corp-Blr | K13: =VLOOKUP(B13,'PO with created By ASR'!A:I,6,FALSE) -> #N/A | L13: =VLOOKUP(B13,'PO with created By ASR'!A:J,7,FALSE) -> B - Bangalore | M13: =VLOOKUP(B13,'PO with created By ASR'!A:K,8,FALSE) -> Purchase Order-Blr | N13: Invoices for inward supply from unregistered person | P13: 6
... B3105: A/2025/PO/000987 | C3105: Air Fare (General) | D3105: 1 | E3105: 29997 | F3105: 29997 | G3105: =VLOOKUP(B3105,'PO with created By ASR'!A:C,3,FALSE) -> 45715 | J3105: =VLOOKUP(B3105,'PO with created By ASR'!A:G,4,FALSE) -> Musafir.Com India Pvt Ltd-Mum | K3105: =VLOOKUP(B3105,'PO with created By ASR'!A:I,6,FALSE) -> 10060 Musafir.Com India Pvt Ltd | L3105: =VLOOKUP(B3105,'PO with created By ASR'!A:J,7,FALSE) -> A - Mumbai | M3105: =VLOOKUP(B3105,'PO with created By ASR'!A:K,8,FALSE) -> Purchase Order-Mum | N3105: Invoices for inward supply from unregistered person | P3105: 6
