Workbook

Sheet April - May All Journal 
A1: Internal ID | B1: Internal ID | C1: Date | D1: Period | E1: Type | F1: Voucher Number | G1: Name | H1: Account | I1: Memo | J1: Amount
A2: 3371 | B2: 3371 | C2: 45748 | D2: Apr 2025 | E2: Journal | F2: A/2025/JV/1525 | G2: 1045050 Padmakar Jadhav | H2: 1252 LOANS, SECURITY & OTHER RECEIVABLES < 1YEAR : OTHER LOANS & ADVANCES : Advance To Employees | J2: 434
A3: 3376 | B3: 3376 | C3: 45776 | D3: Apr 2025 | E3: Journal | F3: A/2025/JV/1981 | G3: 1044833 Nazia M | H3: 10340 LOANS, SECURITY & OTHER RECEIVABLES < 1YEAR : LOANS TO EMPLOYEES | J3: -42000
A4: 3387 | B4: 3387 | C4: 45776 | D4: Apr 2025 | E4: Journal | F4: A/2025/JV/1985 | G4: 1044945 Pravin Mahajan | H4: 1133 STAFF RELATED LIABILITIES (NO BONUSES) : SALARY & WAGES PAYABLE : Reimbursement | I4: Being Provision for Reimbursement for the month of April 2025 | J4: 32500
A5: 3387 | B5: 3387 | C5: 45776 | D5: Apr 2025 | E5: Journal | F5: A/2025/JV/1985 | G5: 1044810 Sidhant Saxena | H5: 1133 STAFF RELATED LIABILITIES (NO BONUSES) : SALARY & WAGES PAYABLE : Reimbursement | I5: Being Provision for Reimbursement for the month of April 2025 | J5: 32500
A6: 3387 | B6: 3387 | C6: 45776 | D6: Apr 2025 | E6: Journal | F6: A/2025/JV/1985 | G6: 1115298 Sony Parikh | H6: 1133 STAFF RELATED LIABILITIES (NO BONUSES) : SALARY & WAGES PAYABLE : Reimbursement | I6: Being Provision for Reimbursement for the month of April 2025 | J6: 30000
A7: 3387 | B7: 3387 | C7: 45776 | D7: Apr 2025 | E7: Journal | F7: A/2025/JV/1985 | G7: 1138617 Tejas Damania | H7: 1133 STAFF RELATED LIABILITIES (NO BONUSES) : SALARY & WAGES PAYABLE : Reimbursement | I7: Being Provision for Reimbursement for the month of April 2025 | J7: 24000
A8: 3390 | B8: 3390 | C8: 45776 | D8: Apr 2025 | E8: Journal | F8: A/2025/JV/1973 | G8: 1143735 Arun Kumar M | H8: 1252 LOANS, SECURITY & OTHER RECEIVABLES < 1YEAR : OTHER LOANS & ADVANCES : Advance To Employees | I8: Being Advance Account Recoverd from Salary for the month of April 2025 | J8: -5291
A9: 3390 | B9: 3390 | C9: 45776 | D9: Apr 2025 | E9: Journal | F9: A/2025/JV/1973 | G9: 1119879 Kapeel Parmekar | H9: 1252 LOANS, SECURITY & OTHER RECEIVABLES < 1YEAR : OTHER LOANS & ADVANCES : Advance To Employees | I9: Being Advance Account Recoverd from Salary for the month of April 2025 | J9: -13398.56
A10: 3390 | B10: 3390 | C10: 45776 | D10: Apr 2025 | E10: Journal | F10: A/2025/JV/1973 | G10: 1144574 Mahesh D | H10: 1252 LOANS, SECURITY & OTHER RECEIVABLES < 1YEAR : OTHER LOANS & ADVANCES : Advance To Employees | I10: Being Advance Account Recoverd from Salary for the month of April 2025 | J10: -1852
A11: 3404 | B11: 3404 | C11: 45748 | D11: Apr 2025 | E11: Journal | F11: A/2025/JV/1534 | G11: 1044950 Santosh Singh | H11: 1252 LOANS, SECURITY & OTHER RECEIVABLES < 1YEAR : OTHER LOANS & ADVANCES : Advance To Employees | I11: Being on Account to Santosh Singh for SB 22540 SAP Now 2025 | J11: 25000
A12: 3458 | B12: 3458 | C12: 45748 | D12: Apr 2025 | E12: Journal | F12: A/2025/JV/1535 | G12: 1126217 Ritu Vohra | H12: 1252 LOANS, SECURITY & OTHER RECEIVABLES < 1YEAR : OTHER LOANS & ADVANCES : Advance To Employees | I12: Being on Account to Ritu Vohra for BU 7 SB 15860 Meeting | J12: 17000
A13: 3459 | B13: 3459 | C13: 45748 | D13: Apr 2025 | E13: Journal | F13: A/2025/JV/1536 | G13: 1133840 Srinivasa Dasari | H13: 1252 LOANS, SECURITY & OTHER RECEIVABLES < 1YEAR : OTHER LOANS & ADVANCES : Advance To Employees | I13: Being on Account to Srinivasa Dasari for BU 9 Bangalore SB 22565 Apparel Fashion Tech World on 04.04.2025 | J13: 13530
A14: 3460 | B14: 3460 | C14: 45748 | D14: Apr 2025 | E14: Journal | F14: A/2025/JV/1537 | G14: 1044966 Harshit Jain | H14: 1252 LOANS, SECURITY & OTHER RECEIVABLES < 1YEAR : OTHER LOANS & ADVANCES : Advance To Employees | I14: Being on Account to Harshit Jain for SB 22344 BU 7 A Github Galaxy 2025 | J14: 100000
A15: 3461 | B15: 3461 | C15: 45748 | D15: Apr 2025 | E15: Journal | F15: A/2025/JV/1538 | G15: 1044826 Hazarat Ansari | H15: 1252 LOANS, SECURITY & OTHER RECEIVABLES < 1YEAR : OTHER LOANS & ADVANCES : Advance To Employees | I15: Being On Account to Hazarat Ansari for BU 1 Rajesh SB 22511 Accenture Interns Welcome Networking Dinner. | J15: 10000
... A215: 4696 | B215: 4696 | C215: 45764 | D215: Apr 2025 | E215: Journal | F215: A/2025/JV/1730 | G215: 1044827 Abdul Rahman | H215: 1252 LOANS, SECURITY & OTHER RECEIVABLES < 1YEAR : OTHER LOANS & ADVANCES : Advance To Employees | I215: Being On Account to Abdul Rehman for SB 22559 HPE Cloud Connect. | J215: 10000
A216: 4697 | B216: 4697 | C216: 45748 | D216: Apr 2025 | E216: Journal | F216: A/2025/JV/1515/Rev | G216: 13128 Credit Card Dues (MIS) Credit Card Dues (MIS) | H216: Accounts Payable | J216: -26496206
A217: 4698 | B217: 4698 | C217: 45764 | D217: Apr 2025 | E217: Journal | F217: A/2025/JV/1731 | G217: 1137927 Chahek Poddar | H217: 1252 LOANS, SECURITY & OTHER RECEIVABLES < 1YEAR : OTHER LOANS & ADVANCES : Advance To Employees | I217: Being Fund Transfer to Chahek Poddar for Credit Balance. | J217: 25244.38
A218: 4699 | B218: 4699 | C218: 45764 | D218: Apr 2025 | E218: Journal | F218: A/2025/JV/1732 | G218: 1044898 Hari Bailwal | H218: 1252 LOANS, SECURITY & OTHER RECEIVABLES < 1YEAR : OTHER LOANS & ADVANCES : Advance To Employees | I218: Being Fund Transfer to Hari Bailwal for Credit Balance. | J218: 36228.94
A219: 4700 | B219: 4700 | C219: 45764 | D219: Apr 2025 | E219: Journal | F219: A/2025/JV/1733 | G219: 1044806 Mangesh Waghmare | H219: 1252 LOANS, SECURITY & OTHER RECEIVABLES < 1YEAR : OTHER LOANS & ADVANCES : Advance To Employees | I219: Being Fund transfer to Mangesh Waghmare for Credit Balance. | J219: 3562
A220: 4701 | B220: 4701 | C220: 45764 | D220: Apr 2025 | E220: Journal | F220: A/2025/JV/1734 | G220: 1143742 Mohammad Danish | H220: 1252 LOANS, SECURITY & OTHER RECEIVABLES < 1YEAR : OTHER LOANS & ADVANCES : Advance To Employees | I220: Being Fund Transfer to Mohammad Danish for Credit Balance. | J220: 10412
A221: 4702 | B221: 4702 | C221: 45764 | D221: Apr 2025 | E221: Journal | F221: A/2025/JV/1735 | G221: 1133034 Pinky Sharma | H221: 1252 LOANS, SECURITY & OTHER RECEIVABLES < 1YEAR : OTHER LOANS & ADVANCES : Advance To Employees | I221: Being Fund Transfer to Pinky Sharma for Credit Balance. | J221: 1300
A222: 4703 | B222: 4703 | C222: 45764 | D222: Apr 2025 | E222: Journal | F222: A/2025/JV/1736 | G222: 1044950 Santosh Singh | H222: 1252 LOANS, SECURITY & OTHER RECEIVABLES < 1YEAR : OTHER LOANS & ADVANCES : Advance To Employees | I222: Being fund transfer to Santosh Singh for Credit Balance. | J222: 20471
A223: 4704 | B223: 4704 | C223: 45764 | D223: Apr 2025 | E223: Journal | F223: A/2025/JV/1737 | G223: 1140518 Tapish Gupta | H223: 1252 LOANS, SECURITY & OTHER RECEIVABLES < 1YEAR : OTHER LOANS & ADVANCES : Advance To Employees | I223: Being fund transfer to Tapish Gupta for Credit Balance. | J223: 5394.87
A224: 4705 | B224: 4705 | C224: 45764 | D224: Apr 2025 | E224: Journal | F224: A/2025/JV/1738 | G224: 1138730 Bitu Kumar | H224: 1252 LOANS, SECURITY & OTHER RECEIVABLES < 1YEAR : OTHER LOANS & ADVANCES : Advance To Employees | I224: Being On Account to Bitu Kumar for SB 15860 . | J224: 10000
A225: 4706 | B225: 4706 | C225: 45764 | D225: Apr 2025 | E225: Journal | F225: A/2025/JV/1739 | G225: 1131024 Anurama V | H225: 1252 LOANS, SECURITY & OTHER RECEIVABLES < 1YEAR : OTHER LOANS & ADVANCES : Advance To Employees | I225: Being On Account to Anurama V for Geberal Expenses. | J225: 1913
A226: 4707 | B226: 4707 | C226: 45764 | D226: Apr 2025 | E226: Journal | F226: A/2025/JV/1740 | G226: 1044863 Sunil Sawant | H226: 1252 LOANS, SECURITY & OTHER RECEIVABLES < 1YEAR : OTHER LOANS & ADVANCES : Advance To Employees | I226: Being On Account to Sunil Sawant for SB 22606 TCS W10K 2025. | J226: 40000
A227: 4708 | B227: 4708 | C227: 45764 | D227: Apr 2025 | E227: Journal | F227: A/2025/JV/1741 | G227: 1045047 Sanil Thombare | H227: 1252 LOANS, SECURITY & OTHER RECEIVABLES < 1YEAR : OTHER LOANS & ADVANCES : Advance To Employees | I227: Being On Account to Sanil Thombare for SB 20100 General Expenses. | J227: 5000
A228: 4709 | B228: 4709 | C228: 45765 | D228: Apr 2025 | E228: Journal | F228: A/2025/JV/1742 | G228: 1044942 Ashwath Rao | H228: 1252 LOANS, SECURITY & OTHER RECEIVABLES < 1YEAR : OTHER LOANS & ADVANCES : Advance To Employees | I228: Being On Account to Ashwath TV for SB 22617 Cognizant NW visit. | J228: 3000
... A234: 4718 | B234: 4718 | C234: 45766 | D234: Apr 2025 | E234: Journal | F234: A/2025/JV/1749 | G234: 1138930 Anandan R | H234: 1252 LOANS, SECURITY & OTHER RECEIVABLES < 1YEAR : OTHER LOANS & ADVANCES : Advance To Employees | I234: Being On Account to R Anandan for BU 8 Chennai SB 22627 Natwest Nasscom GCC Summit 2025. | J234: 27500
A235: 4784 | B235: 4784 | C235: 45777 | D235: Apr 2025 | E235: Journal | F235: A/2025/JV/2032 | G235: 13128 Credit Card Dues (MIS) Credit Card Dues (MIS) | H235: Accounts Payable | J235: 23042960
A236: 4811 | B236: 4811 | C236: 45789 | D236: May 2025 | E236: Journal | F236: A/2025/JV/2143 | G236: 1044808 Sarita Stokes | H236: 1252 LOANS, SECURITY & OTHER RECEIVABLES < 1YEAR : OTHER LOANS & ADVANCES : Advance To Employees | I236: Being On Account to Atish Pawar for SB 20190 EC Expenses Submited to be Sarita Stokes | J236: 8000
A237: 4947 | B237: 4947 | C237: 45794 | D237: May 2025 | E237: Journal | F237: A/2025/JV/2189 | G237: 1136203 Sumit Sangle | H237: 1252 LOANS, SECURITY & OTHER RECEIVABLES < 1YEAR : OTHER LOANS & ADVANCES : Advance To Employees | I237: Being on Account to Sumit Sangle for BU 6 Pravin SB 22691 HUL Dove Scalp Launch Event. | J237: 65000
A238: 4948 | B238: 4948 | C238: 45794 | D238: May 2025 | E238: Journal | F238: A/2025/JV/2190 | G238: 1143165 Karan Nischal | H238: 1252 LOANS, SECURITY & OTHER RECEIVABLES < 1YEAR : OTHER LOANS & ADVANCES : Advance To Employees | I238: Being On Account to Karan Nichal for SB 22561 Dell - Indian Express events in May - 21. | J238: 10000
A239: 4949 | B239: 4949 | C239: 45794 | D239: May 2025 | E239: Journal | F239: A/2025/JV/2191 | G239: 1140645 Seemant Mahalwal | H239: 1252 LOANS, SECURITY & OTHER RECEIVABLES < 1YEAR : OTHER LOANS & ADVANCES : Advance To Employees | I239: Being on Account to Seemant Mahalwal for BU 7 A SB 22657 Google YT Shopping Lifestyle edition. | J239: 5000
A240: 4950 | B240: 4950 | C240: 45794 | D240: May 2025 | E240: Journal | F240: A/2025/JV/2192 | G240: 1045051 Suresh Pardale | H240: 1252 LOANS, SECURITY & OTHER RECEIVABLES < 1YEAR : OTHER LOANS & ADVANCES : Advance To Employees | I240: Being On Account to Suresh Pardale for SB 20100 General Expenses. | J240: 10000
A241: 4951 | B241: 4951 | C241: 45794 | D241: May 2025 | E241: Journal | F241: A/2025/JV/2193 | G241: 1139551 Kapoor Samarth | H241: 1252 LOANS, SECURITY & OTHER RECEIVABLES < 1YEAR : OTHER LOANS & ADVANCES : Advance To Employees | I241: Being On Account to Samarth Kapoor for BU 7 A SB 22690 Vast Data Swags. | J241: 20000
A242: 4952 | B242: 4952 | C242: 45794 | D242: May 2025 | E242: Journal | F242: A/2025/JV/2194 | G242: 1139551 Kapoor Samarth | H242: 1252 LOANS, SECURITY & OTHER RECEIVABLES < 1YEAR : OTHER LOANS & ADVANCES : Advance To Employees | I242: Being on Account to Samarth Kapoor for BU 7 A SB 22690 Vast Data Swags. | J242: 5000
A243: 4953 | B243: 4953 | C243: 45794 | D243: May 2025 | E243: Journal | F243: A/2025/JV/2195 | G243: 1141533 Kunwar Singh Chauhan | H243: 1252 LOANS, SECURITY & OTHER RECEIVABLES < 1YEAR : OTHER LOANS & ADVANCES : Advance To Employees | I243: Being On Account to Kunwar Singh Chauhan for BU 7A SB 22664 Amway BBS Multicity events. | J243: 20500
A244: 4954 | B244: 4954 | C244: 45794 | D244: May 2025 | E244: Journal | F244: A/2025/JV/2196 | G244: 1138381 Naveen Mandal | H244: 1252 LOANS, SECURITY & OTHER RECEIVABLES < 1YEAR : OTHER LOANS & ADVANCES : Advance To Employees | I244: Being On Account to Naveen Mandal for BU 7A SB 22664 Amway BBS Multicity events. | J244: 10000
...

Sheet April - May Applied Journal 
A1: Internal ID | B1: Date | C1: Period | D1: Type | E1: Voucher Number | F1: Name | G1: Account | H1: Memo | I1: Amount | J1: Type | K1: Journal ID | L1: Journal voucher no | M1: Journal Name | N1: Journal account | O1: Journal amount | P1: Journal Pattern | Q1: Journal voucher no
A2: 7749 | B2: 45751 | C2: Apr 2025 | D2: Bill Payment | E2: A/2025/VP/000942 | F2: 12840 Shah Jaju & Associates Shah Jaju & Associates | G2: Accounts Payable | I2: -15388 | J2: Journal | K2: 6535 | L2: A/2025/JV/2110837102 | M2: 12840 Shah Jaju & Associates Shah Jaju & Associates | N2: Accounts Payable | O2: 0.16 | P2: =_xlfn.CONCAT(K2,M2,N2,O2) -> 653512840 Shah Jaju & Associates Shah Jaju & AssociatesAccounts Payable0.16 | Q2: A/2025/JV/2110837102
A3: 7758 | B3: 45756 | C3: Apr 2025 | D3: Bill Payment | E3: A/2025/VP/001008 | F3: 12244 Pcss Solutions Pvt Ltd Pcss Solutions Pvt Ltd | G3: Accounts Payable | I3: -281604 | J3: Journal | K3: 6562 | L3: A/2025/JV/2110837129 | M3: 12244 Pcss Solutions Pvt Ltd Pcss Solutions Pvt Ltd | N3: Accounts Payable | O3: 0.01 | P3: =_xlfn.CONCAT(K3,M3,N3,O3) -> 656212244 Pcss Solutions Pvt Ltd Pcss Solutions Pvt LtdAccounts Payable0.01 | Q3: A/2025/JV/2110837129
A4: 8791 | B4: 45761 | C4: Apr 2025 | D4: Bill Payment | E4: A/2025/VP/001052 | F4: 10229 Tata Teleservices (Mahrashtra) Ltd Tata Teleservices (Mahrashtra) Ltd | G4: Accounts Payable | I4: -2359 | J4: Journal | K4: 7787 | L4: A/2025/JV/2110837208 | M4: 10229 Tata Teleservices (Mahrashtra) Ltd Tata Teleservices (Mahrashtra) Ltd | N4: Accounts Payable | O4: 0.18 | P4: =_xlfn.CONCAT(K4,M4,N4,O4) -> 778710229 Tata Teleservices (Mahrashtra) Ltd Tata Teleservices (Mahrashtra) LtdAccounts Payable0.18 | Q4: A/2025/JV/2110837208
A5: 8822 | B5: 45775 | C5: Apr 2025 | D5: Bill Payment | E5: A/2025/VP/001255 | F5: 10200 Protean eGov Technologies Ltd Protean eGov Technologies Ltd | G5: Accounts Payable | I5: -419 | J5: Journal | K5: 7837 | L5: A/2025/JV/2110837215 | M5: 10200 Protean eGov Technologies Ltd Protean eGov Technologies Ltd | N5: Accounts Payable | O5: 0.39 | P5: =_xlfn.CONCAT(K5,M5,N5,O5) -> 783710200 Protean eGov Technologies Ltd Protean eGov Technologies LtdAccounts Payable0.39 | Q5: A/2025/JV/2110837215
A6: 9175 | B6: 45762 | C6: Apr 2025 | D6: Bill Payment | E6: A/2025/VP/001093 | F6: 11008 Zinia Natasha Fernandes Zinia Natasha Fernandes | G6: 10530 ACCOUNTS PAYABLE : ACCOUNTS PAYABLE | I6: -46800 | J6: Journal | K6: 9090 | L6: A/2025/JV/1565 | M6: 11008 Zinia Natasha Fernandes Zinia Natasha Fernandes | N6: 10530 ACCOUNTS PAYABLE : ACCOUNTS PAYABLE | O6: 28800 | P6: =_xlfn.CONCAT(K6,M6,N6,O6) -> 909011008 Zinia Natasha Fernandes Zinia Natasha Fernandes10530 ACCOUNTS PAYABLE : ACCOUNTS PAYABLE28800 | Q6: A/2025/JV/1565
A7: 9312 | B7: 45758 | C7: Apr 2025 | D7: Bill Payment | E7: B/2025/VP/000467 | F7: 11520 Lynx Security & Detectives Services (P) Ltd Lynx Security & Detectives Services (P) Ltd | G7: Accounts Payable | I7: -26856 | J7: Journal | K7: 8932 | L7: B/2025/JV/2110837301 | M7: 11520 Lynx Security & Detectives Services (P) Ltd Lynx Security & Detectives Services (P) Ltd | N7: Accounts Payable | O7: 0.82 | P7: =_xlfn.CONCAT(K7,M7,N7,O7) -> 893211520 Lynx Security & Detectives Services (P) Ltd Lynx Security & Detectives Services (P) LtdAccounts Payable0.82 | Q7: B/2025/JV/2110837301
A8: 10803 | B8: 45785 | C8: May 2025 | D8: Bill Payment | E8: A/2025/VP/001345 | F8: 10222 S P Sanghi Airconditioning Pvt Ltd S P Sanghi Airconditioning Pvt Ltd | G8: Accounts Payable | I8: -72890 | J8: Journal | K8: 9818 | L8: A/2025/JV/2110837332 | M8: 10222 S P Sanghi Airconditioning Pvt Ltd S P Sanghi Airconditioning Pvt Ltd | N8: Accounts Payable | O8: 0.16 | P8: =_xlfn.CONCAT(K8,M8,N8,O8) -> 981810222 S P Sanghi Airconditioning Pvt Ltd S P Sanghi Airconditioning Pvt LtdAccounts Payable0.16 | Q8: A/2025/JV/2110837332
A9: 10803 | B9: 45785 | C9: May 2025 | D9: Bill Payment | E9: A/2025/VP/001345 | F9: 10222 S P Sanghi Airconditioning Pvt Ltd S P Sanghi Airconditioning Pvt Ltd | G9: Accounts Payable | I9: -72890 | J9: Journal | K9: 12509 | L9: A/2025/JV/2110837422 | M9: 10222 S P Sanghi Airconditioning Pvt Ltd S P Sanghi Airconditioning Pvt Ltd | N9: Accounts Payable | O9: 0.2 | P9: =_xlfn.CONCAT(K9,M9,N9,O9) -> 1250910222 S P Sanghi Airconditioning Pvt Ltd S P Sanghi Airconditioning Pvt LtdAccounts Payable0.2 | Q9: A/2025/JV/2110837422
A10: 10841 | B10: 45791 | C10: May 2025 | D10: Bill Payment | E10: A/2025/VP/001386 | F10: 12067 Jyoti Fire Services Jyoti Fire Services | G10: Accounts Payable | I10: -4142 | J10: Journal | K10: 6536 | L10: A/2025/JV/2110837103 | M10: 12067 Jyoti Fire Services Jyoti Fire Services | N10: Accounts Payable | O10: 0.2 | P10: =_xlfn.CONCAT(K10,M10,N10,O10) -> 653612067 Jyoti Fire Services Jyoti Fire ServicesAccounts Payable0.2 | Q10: A/2025/JV/2110837103
A11: 10925 | B11: 45768 | C11: Apr 2025 | D11: Bill Payment | E11: D/2025/VP/000713 | F11: 11509 Blue Dart Express Ltd Blue Dart Express Ltd | G11: Accounts Payable | I11: -10006 | J11: Journal | K11: 7488 | L11: D/2025/JV/2110837197 | M11: 11509 Blue Dart Express Ltd Blue Dart Express Ltd | N11: Accounts Payable | O11: 0.29 | P11: =_xlfn.CONCAT(K11,M11,N11,O11) -> 748811509 Blue Dart Express Ltd Blue Dart Express LtdAccounts Payable0.29 | Q11: D/2025/JV/2110837197
A12: 11695 | B12: 45750 | C12: Apr 2025 | D12: Bill Payment | E12: D/2025/VP/000582 | F12: 11533 Vinod Gupta Vinod Gupta | G12: Accounts Payable | I12: -264111 | J12: Journal | K12: 8129 | L12: D/2025/JV/2110837255 | M12: 11533 Vinod Gupta Vinod Gupta | N12: Accounts Payable | O12: 0.12 | P12: =_xlfn.CONCAT(K12,M12,N12,O12) -> 812911533 Vinod Gupta Vinod GuptaAccounts Payable0.12 | Q12: D/2025/JV/2110837255
A13: 12451 | B13: 45763 | C13: Apr 2025 | D13: Receipt | E13: SEC/A/RVA/2025/0476 | F13: 10619 Singapore Investcorp India Pvt Ltd | G13: 10364 TRADE NOTES AND ACCOUNTS RECEIVABLE : SUNDRY DEBTORS | I13: -377464 | J13: Journal | K13: 6554 | L13: A/2025/JV/2110837121 | M13: 10619 Singapore Investcorp India Pvt Ltd | N13: 10364 TRADE NOTES AND ACCOUNTS RECEIVABLE : SUNDRY DEBTORS | O13: 0.46 | P13: =_xlfn.CONCAT(K13,M13,N13,O13) -> 655410619 Singapore Investcorp India Pvt Ltd10364 TRADE NOTES AND ACCOUNTS RECEIVABLE : SUNDRY DEBTORS0.46 | Q13: A/2025/JV/2110837121
... A62: 21665 | B62: 45790 | C62: May 2025 | D62: Bill Payment | E62: A/2025/VP/001378 | F62: 11069 Dell International Services India Pvt Ltd Dell International Services India Pvt Ltd | G62: Accounts Payable | I62: -604215 | J62: Journal | K62: 26856 | L62: A/2025/JV/2110838515 | M62: 11069 Dell International Services India Pvt Ltd Dell International Services India Pvt Ltd | N62: Accounts Payable | O62: 0.2 | P62: =_xlfn.CONCAT(K62,M62,N62,O62) -> 2685611069 Dell International Services India Pvt Ltd Dell International Services India Pvt LtdAccounts Payable0.2 | Q62: A/2025/JV/2110838515
A63: 22328 | B63: 45799 | C63: May 2025 | D63: Receipt | E63: SEC/A/RVA/2025/0651 | F63: 10246 Metro Cash & Carry India Pvt Ltd | G63: 10364 TRADE NOTES AND ACCOUNTS RECEIVABLE : SUNDRY DEBTORS | H63: A/2025/IN/0595 | I63: -400797.72 | J63: Journal | K63: 8088 | L63: A/2025/JV/2110837253 | M63: 10246 Metro Cash & Carry India Pvt Ltd | N63: 10364 TRADE NOTES AND ACCOUNTS RECEIVABLE : SUNDRY DEBTORS | O63: 0.28 | P63: =_xlfn.CONCAT(K63,M63,N63,O63) -> 808810246 Metro Cash & Carry India Pvt Ltd10364 TRADE NOTES AND ACCOUNTS RECEIVABLE : SUNDRY DEBTORS0.28 | Q63: A/2025/JV/2110837253
A64: 22548 | B64: 45807 | C64: May 2025 | D64: Receipt | E64: SEC/B/RVA/2025/0036 | F64: 10731 Bengaluru Airport Services Ltd | G64: Accounts Receivable | H64: A/2025/IN/0584 Tds 10% | I64: -1935371 | J64: Journal | K64: 24070 | L64: A/2025/JV/2110838192 | M64: 10731 Bengaluru Airport Services Ltd | N64: Accounts Receivable | O64: 0.2 | P64: =_xlfn.CONCAT(K64,M64,N64,O64) -> 2407010731 Bengaluru Airport Services LtdAccounts Receivable0.2 | Q64: A/2025/JV/2110838192
A65: 22897 | B65: 45811 | C65: Jun 2025 | D65: Receipt | E65: SEC/D/RVA/2025/0135 | F65: 10426 Microsoft Corporation (I) Pvt Ltd | G65: Accounts Receivable | H65: D/2025/SB/0153 | I65: -505056.57 | J65: Journal | K65: 17178 | L65: D/2025/JV/2110837741 | M65: 10426 Microsoft Corporation (I) Pvt Ltd | N65: Accounts Receivable | O65: 0.3 | P65: =_xlfn.CONCAT(K65,M65,N65,O65) -> 1717810426 Microsoft Corporation (I) Pvt LtdAccounts Receivable0.3 | Q65: D/2025/JV/2110837741
A66: 23125 | B66: 45814 | C66: Jun 2025 | D66: Receipt | E66: SEC/A/RVA/2025/0715 | F66: 10469 Amway India Enterprises Pvt Ltd Amway India Enterprises Pvt Ltd | G66: 10364 TRADE NOTES AND ACCOUNTS RECEIVABLE : SUNDRY DEBTORS | H66: A/2025/IN/0586 Tds 2% | I66: -9002125.5 | J66: Journal | K66: 8079 | L66: A/2025/JV/2110837250 | M66: 10469 Amway India Enterprises Pvt Ltd Amway India Enterprises Pvt Ltd | N66: 10364 TRADE NOTES AND ACCOUNTS RECEIVABLE : SUNDRY DEBTORS | O66: 0.46 | P66: =_xlfn.CONCAT(K66,M66,N66,O66) -> 807910469 Amway India Enterprises Pvt Ltd Amway India Enterprises Pvt Ltd10364 TRADE NOTES AND ACCOUNTS RECEIVABLE : SUNDRY DEBTORS0.46 | Q66: A/2025/JV/2110837250
A67: 23415 | B67: 45820 | C67: Jun 2025 | D67: Receipt | E67: SEC/A/RVA/2025/0750 | F67: 10262 Renault Nissan Technology & Business Centre India Pvt Ltd | G67: 10364 TRADE NOTES AND ACCOUNTS RECEIVABLE : SUNDRY DEBTORS | H67: A/2025/IN/0626,A/2025/IN/0627 Tds 10% | I67: -962945.2 | J67: Journal | K67: 11732 | L67: A/2025/JV/2110837399 | M67: 10262 Renault Nissan Technology & Business Centre India Pvt Ltd | N67: 10364 TRADE NOTES AND ACCOUNTS RECEIVABLE : SUNDRY DEBTORS | O67: 0.2 | P67: =_xlfn.CONCAT(K67,M67,N67,O67) -> 1173210262 Renault Nissan Technology & Business Centre India Pvt Ltd10364 TRADE NOTES AND ACCOUNTS RECEIVABLE : SUNDRY DEBTORS0.2 | Q67: A/2025/JV/2110837399
A68: 23426 | B68: 45820 | C68: Jun 2025 | D68: Receipt | E68: SEC/A/RVA/2025/0764 | F68: 10583 Hitachi Vantara India Pvt Ltd Hitachi Vantara India Pvt Ltd | G68: 10364 TRADE NOTES AND ACCOUNTS RECEIVABLE : SUNDRY DEBTORS | H68: A/2025/IN/0607 Tds 10% | I68: -3780022.4 | J68: Journal | K68: 10910 | L68: A/2025/JV/2110837376 | M68: 10583 Hitachi Vantara India Pvt Ltd Hitachi Vantara India Pvt Ltd | N68: 10364 TRADE NOTES AND ACCOUNTS RECEIVABLE : SUNDRY DEBTORS | O68: 0.4 | P68: =_xlfn.CONCAT(K68,M68,N68,O68) -> 1091010583 Hitachi Vantara India Pvt Ltd Hitachi Vantara India Pvt Ltd10364 TRADE NOTES AND ACCOUNTS RECEIVABLE : SUNDRY DEBTORS0.4 | Q68: A/2025/JV/2110837376
A69: 23434 | B69: 45820 | C69: Jun 2025 | D69: Receipt | E69: SEC/A/RVA/2025/0765 | F69: 10385 Bangalore International Airport Ltd | G69: Accounts Receivable | H69: A/2025/IN/0650 Tds 10% | I69: -5054476 | J69: Journal | K69: 16156 | L69: B/2025/JV/2110837665 | M69: 10385 Bangalore International Airport Ltd | N69: Accounts Receivable | O69: 0.4 | P69: =_xlfn.CONCAT(K69,M69,N69,O69) -> 1615610385 Bangalore International Airport LtdAccounts Receivable0.4 | Q69: B/2025/JV/2110837665
A70: 23710 | B70: 45800 | C70: May 2025 | D70: Receipt | E70: SEC/B/RVA/2025/0032 | F70: 10221 Dbs Bank India Ltd | G70: 10364 TRADE NOTES AND ACCOUNTS RECEIVABLE : SUNDRY DEBTORS | I70: -1078822.8 | J70: Journal | K70: 12497 | L70: B/2025/JV/2110837418 | M70: 10221 Dbs Bank India Ltd | N70: 10364 TRADE NOTES AND ACCOUNTS RECEIVABLE : SUNDRY DEBTORS | O70: 0.2 | P70: =_xlfn.CONCAT(K70,M70,N70,O70) -> 1249710221 Dbs Bank India Ltd10364 TRADE NOTES AND ACCOUNTS RECEIVABLE : SUNDRY DEBTORS0.2 | Q70: B/2025/JV/2110837418
A71: 24111 | B71: 45839 | C71: Jul 2025 | D71: Bill Payment | E71: A/2025/VP/001820 | F71: 13170 Mera Prints Solutions Mera Prints Solutions | G71: Accounts Payable | I71: -26403 | J71: Journal | K71: 22810 | L71: A/2025/JV/2110838131 | M71: 13170 Mera Prints Solutions Mera Prints Solutions | N71: Accounts Payable | O71: 0.5 | P71: =_xlfn.CONCAT(K71,M71,N71,O71) -> 2281013170 Mera Prints Solutions Mera Prints SolutionsAccounts Payable0.5 | Q71: A/2025/JV/2110838131
A72: 24116 | B72: 45842 | C72: Jul 2025 | D72: Bill Payment | E72: A/2025/VP/001865 | F72: 12244 Pcss Solutions Pvt Ltd Pcss Solutions Pvt Ltd | G72: Accounts Payable | I72: -653727 | J72: Journal | K72: 11013 | L72: A/2025/JV/2110837386 | M72: 12244 Pcss Solutions Pvt Ltd Pcss Solutions Pvt Ltd | N72: Accounts Payable | O72: 0.02 | P72: =_xlfn.CONCAT(K72,M72,N72,O72) -> 1101312244 Pcss Solutions Pvt Ltd Pcss Solutions Pvt LtdAccounts Payable0.02 | Q72: A/2025/JV/2110837386
A73: 24362 | B73: 45768 | C73: Apr 2025 | D73: Bill Payment | E73: D/2025/VP/000711 | F73: 11132 Shree Ram Computers Shree Ram Computers | G73: Accounts Payable | I73: -29275 | J73: Journal | K73: 8405 | L73: D/2025/JV/2110837274 | M73: 11132 Shree Ram Computers Shree Ram Computers | N73: Accounts Payable | O73: 0.06 | P73: =_xlfn.CONCAT(K73,M73,N73,O73) -> 840511132 Shree Ram Computers Shree Ram ComputersAccounts Payable0.06 | Q73: D/2025/JV/2110837274
A74: 24362 | B74: 45768 | C74: Apr 2025 | D74: Bill Payment | E74: D/2025/VP/000711 | F74: 11132 Shree Ram Computers Shree Ram Computers | G74: Accounts Payable | I74: -29275 | J74: Journal | K74: 8374 | L74: D/2025/JV/2110837271 | M74: 11132 Shree Ram Computers Shree Ram Computers | N74: Accounts Payable | O74: 0.36 | P74: =_xlfn.CONCAT(K74,M74,N74,O74) -> 837411132 Shree Ram Computers Shree Ram ComputersAccounts Payable0.36 | Q74: D/2025/JV/2110837271
A75: 24647 | B75: 45804 | C75: May 2025 | D75: Bill Payment | E75: B/2025/VP/000681 | F75: 12133 M/S Megascule M/S Megascule | G75: Accounts Payable | I75: -304978 | J75: Journal | K75: 23850 | L75: B/2025/JV/2110838169 | M75: 12133 M/S Megascule M/S Megascule | N75: Accounts Payable | O75: 0.5 | P75: =_xlfn.CONCAT(K75,M75,N75,O75) -> 2385012133 M/S Megascule M/S MegasculeAccounts Payable0.5 | Q75: B/2025/JV/2110838169
A76: 24660 | B76: 45805 | C76: May 2025 | D76: Bill Payment | E76: B/2025/VP/000688 | F76: 12286 Print With Me Pvt Ltd Print With Me Pvt Ltd | G76: Accounts Payable | I76: -37535 | J76: Journal | K76: 10204 | L76: B/2025/JV/2110837355 | M76: 12286 Print With Me Pvt Ltd Print With Me Pvt Ltd | N76: Accounts Payable | O76: 0.46 | P76: =_xlfn.CONCAT(K76,M76,N76,O76) -> 1020412286 Print With Me Pvt Ltd Print With Me Pvt LtdAccounts Payable0.46 | Q76: B/2025/JV/2110837355
A77: 24663 | B77: 45805 | C77: May 2025 | D77: Bill Payment | E77: B/2025/VP/000690 | F77: 12133 M/S Megascule M/S Megascule | G77: Accounts Payable | I77: -33188 | J77: Journal | K77: 10190 | L77: B/2025/JV/2110837352 | M77: 12133 M/S Megascule M/S Megascule | N77: Accounts Payable | O77: 0.5 | P77: =_xlfn.CONCAT(K77,M77,N77,O77) -> 1019012133 M/S Megascule M/S MegasculeAccounts Payable0.5 | Q77: B/2025/JV/2110837352
A78: 24673 | B78: 45806 | C78: May 2025 | D78: Bill Payment | E78: B/2025/VP/000693 | F78: 11795 Courier International Services Courier International Services | G78: Accounts Payable | I78: -87560 | J78: Journal | K78: 20611 | L78: B/2025/JV/2110837982 | M78: 11795 Courier International Services Courier International Services | N78: Accounts Payable | O78: 0.4 | P78: =_xlfn.CONCAT(K78,M78,N78,O78) -> 2061111795 Courier International Services Courier International ServicesAccounts Payable0.4 | Q78: B/2025/JV/2110837982
A79: 24673 | B79: 45806 | C79: May 2025 | D79: Bill Payment | E79: B/2025/VP/000693 | F79: 11795 Courier International Services Courier International Services | G79: Accounts Payable | I79: -87560 | J79: Journal | K79: 19628 | L79: B/2025/JV/2110837931 | M79: 11795 Courier International Services Courier International Services | N79: Accounts Payable | O79: 0.5 | P79: =_xlfn.CONCAT(K79,M79,N79,O79) -> 1962811795 Courier International Services Courier International ServicesAccounts Payable0.5 | Q79: B/2025/JV/2110837931
A80: 24702 | B80: 45805 | C80: May 2025 | D80: Bill Payment | E80: C/2025/VP/000239 | F80: 11915 Fiesta Car Rentals & Logistics Pvt Ltd Fiesta Car Rentals & Logistics Pvt Ltd | G80: Accounts Payable | I80: -1838 | J80: Journal | K80: 8457 | L80: C/2025/JV/2110837276 | M80: 11915 Fiesta Car Rentals & Logistics Pvt Ltd Fiesta Car Rentals & Logistics Pvt Ltd | N80: Accounts Payable | O80: 0.5 | P80: =_xlfn.CONCAT(K80,M80,N80,O80) -> 845711915 Fiesta Car Rentals & Logistics Pvt Ltd Fiesta Car Rentals & Logistics Pvt LtdAccounts Payable0.5 | Q80: C/2025/JV/2110837276
A81: 24706 | B81: 45811 | C81: Jun 2025 | D81: Bill Payment | E81: C/2025/VP/000243 | F81: 13117 Shellcode Pvt Ltd Shellcode Pvt Ltd | G81: Accounts Payable | I81: -23742 | J81: Journal | K81: 23508 | L81: A/2025/JV/2110838154 | M81: 13117 Shellcode Pvt Ltd Shellcode Pvt Ltd | N81: Accounts Payable | O81: 0.26 | P81: =_xlfn.CONCAT(K81,M81,N81,O81) -> 2350813117 Shellcode Pvt Ltd Shellcode Pvt LtdAccounts Payable0.26 | Q81: A/2025/JV/2110838154
... A109: 32305 | B109: 45825 | C109: Jun 2025 | D109: Bill Payment | E109: D/2025/VP/001063 | F109: 11774 M/S Cockpitmarx M/S Cockpitmarx | G109: Accounts Payable | I109: -402768 | J109: Journal | K109: 27629 | L109: D/2025/JV/2110838634 | M109: 11774 M/S Cockpitmarx M/S Cockpitmarx | N109: Accounts Payable | O109: 0.46 | P109: =_xlfn.CONCAT(K109,M109,N109,O109) -> 2762911774 M/S Cockpitmarx M/S CockpitmarxAccounts Payable0.46 | Q109: D/2025/JV/2110838634
A110: 34050 | B110: 45819 | C110: Jun 2025 | D110: Receipt | E110: SEC/A/RVA/2025/0753 | F110: 10592 Kotak Mahindra Bank Ltd | G110: Accounts Receivable | H110: A/2025/IN/0651 Tds 2% | I110: -857450 | J110: Journal | K110: 14369 | L110: A/2025/JV/2110837603 | M110: 10592 Kotak Mahindra Bank Ltd | N110: Accounts Receivable | O110: 0.24 | P110: =_xlfn.CONCAT(K110,M110,N110,O110) -> 1436910592 Kotak Mahindra Bank LtdAccounts Receivable0.24 | Q110: A/2025/JV/2110837603
A111: 34065 | B111: 45827 | C111: Jun 2025 | D111: Receipt | E111: SEC/A/RVA/2025/0785 | F111: 10642 Amazon Seller Services India Pvt Ltd | G111: Accounts Receivable | H111: A/2025/IN/0667 Tds 2% | I111: -506988.44 | J111: Journal | K111: 16173 | L111: A/2025/JV/2110837669 | M111: 10642 Amazon Seller Services India Pvt Ltd | N111: Accounts Receivable | O111: 0.33 | P111: =_xlfn.CONCAT(K111,M111,N111,O111) -> 1617310642 Amazon Seller Services India Pvt LtdAccounts Receivable0.33 | Q111: A/2025/JV/2110837669
A112: 34096 | B112: 45828 | C112: Jun 2025 | D112: Receipt | E112: SEC/A/RVA/2025/0792 | F112: 10141 Google India Pvt Ltd | G112: 10364 TRADE NOTES AND ACCOUNTS RECEIVABLE : SUNDRY DEBTORS | H112: A/2025/IN/0614 | I112: -289466 | J112: Journal | K112: 10945 | L112: A/2025/JV/2110837382 | M112: 10141 Google India Pvt Ltd | N112: 10364 TRADE NOTES AND ACCOUNTS RECEIVABLE : SUNDRY DEBTORS | O112: 0.2 | P112: =_xlfn.CONCAT(K112,M112,N112,O112) -> 1094510141 Google India Pvt Ltd10364 TRADE NOTES AND ACCOUNTS RECEIVABLE : SUNDRY DEBTORS0.2 | Q112: A/2025/JV/2110837382
A113: 34325 | B113: 45838 | C113: Jun 2025 | D113: Receipt | E113: SEC/A/RVA/2025/0824 | F113: 10181 Siemens Ltd | G113: 10364 TRADE NOTES AND ACCOUNTS RECEIVABLE : SUNDRY DEBTORS | H113: A/2025/IN/0573 Tds 10% | I113: -309809 | J113: Journal | K113: 8632 | L113: A/2025/JV/2110837285 | M113: 10181 Siemens Ltd | N113: 10364 TRADE NOTES AND ACCOUNTS RECEIVABLE : SUNDRY DEBTORS | O113: 0.22 | P113: =_xlfn.CONCAT(K113,M113,N113,O113) -> 863210181 Siemens Ltd10364 TRADE NOTES AND ACCOUNTS RECEIVABLE : SUNDRY DEBTORS0.22 | Q113: A/2025/JV/2110837285
A114: 34338 | B114: 45838 | C114: Jun 2025 | D114: Receipt | E114: SEC/A/RVA/2025/0829 | F114: 10397 Dell International Services India Pvt Ltd | G114: Accounts Receivable | H114: A/2025/IN/0659,A/2025/IN/0660,A/2025/IN/0661,A/2025/IN/0662 Tds 10% | I114: -19590414 | J114: Journal | K114: 18248 | L114: D/2025/JV/2110837793 | M114: 10397 Dell International Services India Pvt Ltd | N114: Accounts Receivable | O114: 0.4 | P114: =_xlfn.CONCAT(K114,M114,N114,O114) -> 1824810397 Dell International Services India Pvt LtdAccounts Receivable0.4 | Q114: D/2025/JV/2110837793
A115: 34442 | B115: 45839 | C115: Jul 2025 | D115: Receipt | E115: SEC/A/RVA/2025/0834 | F115: 10412 Hindustan Unilever Ltd | G115: Accounts Receivable | H115: A/2025/IN/0663 Tds 1.90% | I115: -1039150.8 | J115: Journal | K115: 18254 | L115: A/2025/JV/2110837796 | M115: 10412 Hindustan Unilever Ltd | N115: Accounts Receivable | O115: 0.23 | P115: =_xlfn.CONCAT(K115,M115,N115,O115) -> 1825410412 Hindustan Unilever LtdAccounts Receivable0.23 | Q115: A/2025/JV/2110837796
...

Sheet April - May Not Applied Matchin
A1: Internal ID | B1: Date | C1: Period | D1: Type | E1: Voucher Number | F1: Name | G1: Account | H1: Memo | I1: Amount | J1: Journal Pattern
A2: 3371 | B2: 45748 | C2: Apr 2025 | D2: Journal | E2: A/2025/JV/1525 | F2: 1045050 Padmakar Jadhav | G2: 1252 LOANS, SECURITY & OTHER RECEIVABLES < 1YEAR : OTHER LOANS & ADVANCES : Advance To Employees | I2: 434 | J2: =_xlfn.CONCAT(A2,F2,G2,I2) -> 33711045050 Padmakar Jadhav1252 LOANS, SECURITY & OTHER RECEIVABLES < 1YEAR : OTHER LOANS & ADVANCES : Advance To Employees434 | K2: =VLOOKUP(J2,'April - May Applied Journal '!P:Q,2,FALSE) -> #N/A
A3: 3376 | B3: 45776 | C3: Apr 2025 | D3: Journal | E3: A/2025/JV/1981 | F3: 1044833 Nazia M | G3: 10340 LOANS, SECURITY & OTHER RECEIVABLES < 1YEAR : LOANS TO EMPLOYEES | I3: -42000 | J3: =_xlfn.CONCAT(A3,F3,G3,I3) -> 33761044833 Nazia M10340 LOANS, SECURITY & OTHER RECEIVABLES < 1YEAR : LOANS TO EMPLOYEES-42000 | K3: =VLOOKUP(J3,'April - May Applied Journal '!P:Q,2,FALSE) -> #N/A
A4: 3387 | B4: 45776 | C4: Apr 2025 | D4: Journal | E4: A/2025/JV/1985 | F4: 1044945 Pravin Mahajan | G4: 1133 STAFF RELATED LIABILITIES (NO BONUSES) : SALARY & WAGES PAYABLE : Reimbursement | H4: Being Provision for Reimbursement for the month of April 2025 | I4: 32500 | J4: =_xlfn.CONCAT(A4,F4,G4,I4) -> 33871044945 Pravin Mahajan1133 STAFF RELATED LIABILITIES (NO BONUSES) : SALARY & WAGES PAYABLE : Reimbursement32500 | K4: =VLOOKUP(J4,'April - May Applied Journal '!P:Q,2,FALSE) -> #N/A
A5: 3387 | B5: 45776 | C5: Apr 2025 | D5: Journal | E5: A/2025/JV/1985 | F5: 1044810 Sidhant Saxena | G5: 1133 STAFF RELATED LIABILITIES (NO BONUSES) : SALARY & WAGES PAYABLE : Reimbursement | H5: Being Provision for Reimbursement for the month of April 2025 | I5: 32500 | J5: =_xlfn.CONCAT(A5,F5,G5,I5) -> 33871044810 Sidhant Saxena1133 STAFF RELATED LIABILITIES (NO BONUSES) : SALARY & WAGES PAYABLE : Reimbursement32500 | K5: =VLOOKUP(J5,'April - May Applied Journal '!P:Q,2,FALSE) -> #N/A
A6: 3387 | B6: 45776 | C6: Apr 2025 | D6: Journal | E6: A/2025/JV/1985 | F6: 1115298 Sony Parikh | G6: 1133 STAFF RELATED LIABILITIES (NO BONUSES) : SALARY & WAGES PAYABLE : Reimbursement | H6: Being Provision for Reimbursement for the month of April 2025 | I6: 30000 | J6: =_xlfn.CONCAT(A6,F6,G6,I6) -> 33871115298 Sony Parikh1133 STAFF RELATED LIABILITIES (NO BONUSES) : SALARY & WAGES PAYABLE : Reimbursement30000 | K6: =VLOOKUP(J6,'April - May Applied Journal '!P:Q,2,FALSE) -> #N/A
A7: 3387 | B7: 45776 | C7: Apr 2025 | D7: Journal | E7: A/2025/JV/1985 | F7: 1138617 Tejas Damania | G7: 1133 STAFF RELATED LIABILITIES (NO BONUSES) : SALARY & WAGES PAYABLE : Reimbursement | H7: Being Provision for Reimbursement for the month of April 2025 | I7: 24000 | J7: =_xlfn.CONCAT(A7,F7,G7,I7) -> 33871138617 Tejas Damania1133 STAFF RELATED LIABILITIES (NO BONUSES) : SALARY & WAGES PAYABLE : Reimbursement24000 | K7: =VLOOKUP(J7,'April - May Applied Journal '!P:Q,2,FALSE) -> #N/A
A8: 3390 | B8: 45776 | C8: Apr 2025 | D8: Journal | E8: A/2025/JV/1973 | F8: 1143735 Arun Kumar M | G8: 1252 LOANS, SECURITY & OTHER RECEIVABLES < 1YEAR : OTHER LOANS & ADVANCES : Advance To Employees | H8: Being Advance Account Recoverd from Salary for the month of April 2025 | I8: -5291 | J8: =_xlfn.CONCAT(A8,F8,G8,I8) -> 33901143735 Arun Kumar M1252 LOANS, SECURITY & OTHER RECEIVABLES < 1YEAR : OTHER LOANS & ADVANCES : Advance To Employees-5291 | K8: =VLOOKUP(J8,'April - May Applied Journal '!P:Q,2,FALSE) -> #N/A
A9: 3390 | B9: 45776 | C9: Apr 2025 | D9: Journal | E9: A/2025/JV/1973 | F9: 1119879 Kapeel Parmekar | G9: 1252 LOANS, SECURITY & OTHER RECEIVABLES < 1YEAR : OTHER LOANS & ADVANCES : Advance To Employees | H9: Being Advance Account Recoverd from Salary for the month of April 2025 | I9: -13398.56 | J9: =_xlfn.CONCAT(A9,F9,G9,I9) -> 33901119879 Kapeel Parmekar1252 LOANS, SECURITY & OTHER RECEIVABLES < 1YEAR : OTHER LOANS & ADVANCES : Advance To Employees-13398.56 | K9: =VLOOKUP(J9,'April - May Applied Journal '!P:Q,2,FALSE) -> #N/A
A10: 3390 | B10: 45776 | C10: Apr 2025 | D10: Journal | E10: A/2025/JV/1973 | F10: 1144574 Mahesh D | G10: 1252 LOANS, SECURITY & OTHER RECEIVABLES < 1YEAR : OTHER LOANS & ADVANCES : Advance To Employees | H10: Being Advance Account Recoverd from Salary for the month of April 2025 | I10: -1852 | J10: =_xlfn.CONCAT(A10,F10,G10,I10) -> 33901144574 Mahesh D1252 LOANS, SECURITY & OTHER RECEIVABLES < 1YEAR : OTHER LOANS & ADVANCES : Advance To Employees-1852 | K10: =VLOOKUP(J10,'April - May Applied Journal '!P:Q,2,FALSE) -> #N/A
A11: 3404 | B11: 45748 | C11: Apr 2025 | D11: Journal | E11: A/2025/JV/1534 | F11: 1044950 Santosh Singh | G11: 1252 LOANS, SECURITY & OTHER RECEIVABLES < 1YEAR : OTHER LOANS & ADVANCES : Advance To Employees | H11: Being on Account to Santosh Singh for SB 22540 SAP Now 2025 | I11: 25000 | J11: =_xlfn.CONCAT(A11,F11,G11,I11) -> 34041044950 Santosh Singh1252 LOANS, SECURITY & OTHER RECEIVABLES < 1YEAR : OTHER LOANS & ADVANCES : Advance To Employees25000 | K11: =VLOOKUP(J11,'April - May Applied Journal '!P:Q,2,FALSE) -> #N/A
A12: 3458 | B12: 45748 | C12: Apr 2025 | D12: Journal | E12: A/2025/JV/1535 | F12: 1126217 Ritu Vohra | G12: 1252 LOANS, SECURITY & OTHER RECEIVABLES < 1YEAR : OTHER LOANS & ADVANCES : Advance To Employees | H12: Being on Account to Ritu Vohra for BU 7 SB 15860 Meeting | I12: 17000 | J12: =_xlfn.CONCAT(A12,F12,G12,I12) -> 34581126217 Ritu Vohra1252 LOANS, SECURITY & OTHER RECEIVABLES < 1YEAR : OTHER LOANS & ADVANCES : Advance To Employees17000 | K12: =VLOOKUP(J12,'April - May Applied Journal '!P:Q,2,FALSE) -> #N/A
A13: 3459 | B13: 45748 | C13: Apr 2025 | D13: Journal | E13: A/2025/JV/1536 | F13: 1133840 Srinivasa Dasari | G13: 1252 LOANS, SECURITY & OTHER RECEIVABLES < 1YEAR : OTHER LOANS & ADVANCES : Advance To Employees | H13: Being on Account to Srinivasa Dasari for BU 9 Bangalore SB 22565 Apparel Fashion Tech World on 04.04.2025 | I13: 13530 | J13: =_xlfn.CONCAT(A13,F13,G13,I13) -> 34591133840 Srinivasa Dasari1252 LOANS, SECURITY & OTHER RECEIVABLES < 1YEAR : OTHER LOANS & ADVANCES : Advance To Employees13530 | K13: =VLOOKUP(J13,'April - May Applied Journal '!P:Q,2,FALSE) -> #N/A
A14: 3460 | B14: 45748 | C14: Apr 2025 | D14: Journal | E14: A/2025/JV/1537 | F14: 1044966 Harshit Jain | G14: 1252 LOANS, SECURITY & OTHER RECEIVABLES < 1YEAR : OTHER LOANS & ADVANCES : Advance To Employees | H14: Being on Account to Harshit Jain for SB 22344 BU 7 A Github Galaxy 2025 | I14: 100000 | J14: =_xlfn.CONCAT(A14,F14,G14,I14) -> 34601044966 Harshit Jain1252 LOANS, SECURITY & OTHER RECEIVABLES < 1YEAR : OTHER LOANS & ADVANCES : Advance To Employees100000 | K14: =VLOOKUP(J14,'April - May Applied Journal '!P:Q,2,FALSE) -> #N/A
A15: 3461 | B15: 45748 | C15: Apr 2025 | D15: Journal | E15: A/2025/JV/1538 | F15: 1044826 Hazarat Ansari | G15: 1252 LOANS, SECURITY & OTHER RECEIVABLES < 1YEAR : OTHER LOANS & ADVANCES : Advance To Employees | H15: Being On Account to Hazarat Ansari for BU 1 Rajesh SB 22511 Accenture Interns Welcome Networking Dinner. | I15: 10000 | J15: =_xlfn.CONCAT(A15,F15,G15,I15) -> 34611044826 Hazarat Ansari1252 LOANS, SECURITY & OTHER RECEIVABLES < 1YEAR : OTHER LOANS & ADVANCES : Advance To Employees10000 | K15: =VLOOKUP(J15,'April - May Applied Journal '!P:Q,2,FALSE) -> #N/A
... A215: 4696 | B215: 45764 | C215: Apr 2025 | D215: Journal | E215: A/2025/JV/1730 | F215: 1044827 Abdul Rahman | G215: 1252 LOANS, SECURITY & OTHER RECEIVABLES < 1YEAR : OTHER LOANS & ADVANCES : Advance To Employees | H215: Being On Account to Abdul Rehman for SB 22559 HPE Cloud Connect. | I215: 10000 | J215: =_xlfn.CONCAT(A215,F215,G215,I215) -> 46961044827 Abdul Rahman1252 LOANS, SECURITY & OTHER RECEIVABLES < 1YEAR : OTHER LOANS & ADVANCES : Advance To Employees10000 | K215: =VLOOKUP(J215,'April - May Applied Journal '!P:Q,2,FALSE) -> #N/A
A216: 4697 | B216: 45748 | C216: Apr 2025 | D216: Journal | E216: A/2025/JV/1515/Rev | F216: 13128 Credit Card Dues (MIS) Credit Card Dues (MIS) | G216: Accounts Payable | I216: -26496206 | J216: =_xlfn.CONCAT(A216,F216,G216,I216) -> 469713128 Credit Card Dues (MIS) Credit Card Dues (MIS)Accounts Payable-26496206.39 | K216: =VLOOKUP(J216,'April - May Applied Journal '!P:Q,2,FALSE) -> #N/A
A217: 4698 | B217: 45764 | C217: Apr 2025 | D217: Journal | E217: A/2025/JV/1731 | F217: 1137927 Chahek Poddar | G217: 1252 LOANS, SECURITY & OTHER RECEIVABLES < 1YEAR : OTHER LOANS & ADVANCES : Advance To Employees | H217: Being Fund Transfer to Chahek Poddar for Credit Balance. | I217: 25244.38 | J217: =_xlfn.CONCAT(A217,F217,G217,I217) -> 46981137927 Chahek Poddar1252 LOANS, SECURITY & OTHER RECEIVABLES < 1YEAR : OTHER LOANS & ADVANCES : Advance To Employees25244.38 | K217: =VLOOKUP(J217,'April - May Applied Journal '!P:Q,2,FALSE) -> #N/A
A218: 4699 | B218: 45764 | C218: Apr 2025 | D218: Journal | E218: A/2025/JV/1732 | F218: 1044898 Hari Bailwal | G218: 1252 LOANS, SECURITY & OTHER RECEIVABLES < 1YEAR : OTHER LOANS & ADVANCES : Advance To Employees | H218: Being Fund Transfer to Hari Bailwal for Credit Balance. | I218: 36228.94 | J218: =_xlfn.CONCAT(A218,F218,G218,I218) -> 46991044898 Hari Bailwal1252 LOANS, SECURITY & OTHER RECEIVABLES < 1YEAR : OTHER LOANS & ADVANCES : Advance To Employees36228.94 | K218: =VLOOKUP(J218,'April - May Applied Journal '!P:Q,2,FALSE) -> #N/A
A219: 4700 | B219: 45764 | C219: Apr 2025 | D219: Journal | E219: A/2025/JV/1733 | F219: 1044806 Mangesh Waghmare | G219: 1252 LOANS, SECURITY & OTHER RECEIVABLES < 1YEAR : OTHER LOANS & ADVANCES : Advance To Employees | H219: Being Fund transfer to Mangesh Waghmare for Credit Balance. | I219: 3562 | J219: =_xlfn.CONCAT(A219,F219,G219,I219) -> 47001044806 Mangesh Waghmare1252 LOANS, SECURITY & OTHER RECEIVABLES < 1YEAR : OTHER LOANS & ADVANCES : Advance To Employees3562 | K219: =VLOOKUP(J219,'April - May Applied Journal '!P:Q,2,FALSE) -> #N/A
A220: 4701 | B220: 45764 | C220: Apr 2025 | D220: Journal | E220: A/2025/JV/1734 | F220: 1143742 Mohammad Danish | G220: 1252 LOANS, SECURITY & OTHER RECEIVABLES < 1YEAR : OTHER LOANS & ADVANCES : Advance To Employees | H220: Being Fund Transfer to Mohammad Danish for Credit Balance. | I220: 10412 | J220: =_xlfn.CONCAT(A220,F220,G220,I220) -> 47011143742 Mohammad Danish1252 LOANS, SECURITY & OTHER RECEIVABLES < 1YEAR : OTHER LOANS & ADVANCES : Advance To Employees10412 | K220: =VLOOKUP(J220,'April - May Applied Journal '!P:Q,2,FALSE) -> #N/A
A221: 4702 | B221: 45764 | C221: Apr 2025 | D221: Journal | E221: A/2025/JV/1735 | F221: 1133034 Pinky Sharma | G221: 1252 LOANS, SECURITY & OTHER RECEIVABLES < 1YEAR : OTHER LOANS & ADVANCES : Advance To Employees | H221: Being Fund Transfer to Pinky Sharma for Credit Balance. | I221: 1300 | J221: =_xlfn.CONCAT(A221,F221,G221,I221) -> 47021133034 Pinky Sharma1252 LOANS, SECURITY & OTHER RECEIVABLES < 1YEAR : OTHER LOANS & ADVANCES : Advance To Employees1300 | K221: =VLOOKUP(J221,'April - May Applied Journal '!P:Q,2,FALSE) -> #N/A
A222: 4703 | B222: 45764 | C222: Apr 2025 | D222: Journal | E222: A/2025/JV/1736 | F222: 1044950 Santosh Singh | G222: 1252 LOANS, SECURITY & OTHER RECEIVABLES < 1YEAR : OTHER LOANS & ADVANCES : Advance To Employees | H222: Being fund transfer to Santosh Singh for Credit Balance. | I222: 20471 | J222: =_xlfn.CONCAT(A222,F222,G222,I222) -> 47031044950 Santosh Singh1252 LOANS, SECURITY & OTHER RECEIVABLES < 1YEAR : OTHER LOANS & ADVANCES : Advance To Employees20471 | K222: =VLOOKUP(J222,'April - May Applied Journal '!P:Q,2,FALSE) -> #N/A
A223: 4704 | B223: 45764 | C223: Apr 2025 | D223: Journal | E223: A/2025/JV/1737 | F223: 1140518 Tapish Gupta | G223: 1252 LOANS, SECURITY & OTHER RECEIVABLES < 1YEAR : OTHER LOANS & ADVANCES : Advance To Employees | H223: Being fund transfer to Tapish Gupta for Credit Balance. | I223: 5394.87 | J223: =_xlfn.CONCAT(A223,F223,G223,I223) -> 47041140518 Tapish Gupta1252 LOANS, SECURITY & OTHER RECEIVABLES < 1YEAR : OTHER LOANS & ADVANCES : Advance To Employees5394.87 | K223: =VLOOKUP(J223,'April - May Applied Journal '!P:Q,2,FALSE) -> #N/A
A224: 4705 | B224: 45764 | C224: Apr 2025 | D224: Journal | E224: A/2025/JV/1738 | F224: 1138730 Bitu Kumar | G224: 1252 LOANS, SECURITY & OTHER RECEIVABLES < 1YEAR : OTHER LOANS & ADVANCES : Advance To Employees | H224: Being On Account to Bitu Kumar for SB 15860 . | I224: 10000 | J224: =_xlfn.CONCAT(A224,F224,G224,I224) -> 47051138730 Bitu Kumar1252 LOANS, SECURITY & OTHER RECEIVABLES < 1YEAR : OTHER LOANS & ADVANCES : Advance To Employees10000 | K224: =VLOOKUP(J224,'April - May Applied Journal '!P:Q,2,FALSE) -> #N/A
A225: 4706 | B225: 45764 | C225: Apr 2025 | D225: Journal | E225: A/2025/JV/1739 | F225: 1131024 Anurama V | G225: 1252 LOANS, SECURITY & OTHER RECEIVABLES < 1YEAR : OTHER LOANS & ADVANCES : Advance To Employees | H225: Being On Account to Anurama V for Geberal Expenses. | I225: 1913 | J225: =_xlfn.CONCAT(A225,F225,G225,I225) -> 47061131024 Anurama V1252 LOANS, SECURITY & OTHER RECEIVABLES < 1YEAR : OTHER LOANS & ADVANCES : Advance To Employees1913 | K225: =VLOOKUP(J225,'April - May Applied Journal '!P:Q,2,FALSE) -> #N/A
A226: 4707 | B226: 45764 | C226: Apr 2025 | D226: Journal | E226: A/2025/JV/1740 | F226: 1044863 Sunil Sawant | G226: 1252 LOANS, SECURITY & OTHER RECEIVABLES < 1YEAR : OTHER LOANS & ADVANCES : Advance To Employees | H226: Being On Account to Sunil Sawant for SB 22606 TCS W10K 2025. | I226: 40000 | J226: =_xlfn.CONCAT(A226,F226,G226,I226) -> 47071044863 Sunil Sawant1252 LOANS, SECURITY & OTHER RECEIVABLES < 1YEAR : OTHER LOANS & ADVANCES : Advance To Employees40000 | K226: =VLOOKUP(J226,'April - May Applied Journal '!P:Q,2,FALSE) -> #N/A
A227: 4708 | B227: 45764 | C227: Apr 2025 | D227: Journal | E227: A/2025/JV/1741 | F227: 1045047 Sanil Thombare | G227: 1252 LOANS, SECURITY & OTHER RECEIVABLES < 1YEAR : OTHER LOANS & ADVANCES : Advance To Employees | H227: Being On Account to Sanil Thombare for SB 20100 General Expenses. | I227: 5000 | J227: =_xlfn.CONCAT(A227,F227,G227,I227) -> 47081045047 Sanil Thombare1252 LOANS, SECURITY & OTHER RECEIVABLES < 1YEAR : OTHER LOANS & ADVANCES : Advance To Employees5000 | K227: =VLOOKUP(J227,'April - May Applied Journal '!P:Q,2,FALSE) -> #N/A
A228: 4709 | B228: 45765 | C228: Apr 2025 | D228: Journal | E228: A/2025/JV/1742 | F228: 1044942 Ashwath Rao | G228: 1252 LOANS, SECURITY & OTHER RECEIVABLES < 1YEAR : OTHER LOANS & ADVANCES : Advance To Employees | H228: Being On Account to Ashwath TV for SB 22617 Cognizant NW visit. | I228: 3000 | J228: =_xlfn.CONCAT(A228,F228,G228,I228) -> 47091044942 Ashwath Rao1252 LOANS, SECURITY & OTHER RECEIVABLES < 1YEAR : OTHER LOANS & ADVANCES : Advance To Employees3000 | K228: =VLOOKUP(J228,'April - May Applied Journal '!P:Q,2,FALSE) -> #N/A
... A234: 4718 | B234: 45766 | C234: Apr 2025 | D234: Journal | E234: A/2025/JV/1749 | F234: 1138930 Anandan R | G234: 1252 LOANS, SECURITY & OTHER RECEIVABLES < 1YEAR : OTHER LOANS & ADVANCES : Advance To Employees | H234: Being On Account to R Anandan for BU 8 Chennai SB 22627 Natwest Nasscom GCC Summit 2025. | I234: 27500 | J234: =_xlfn.CONCAT(A234,F234,G234,I234) -> 47181138930 Anandan R1252 LOANS, SECURITY & OTHER RECEIVABLES < 1YEAR : OTHER LOANS & ADVANCES : Advance To Employees27500 | K234: =VLOOKUP(J234,'April - May Applied Journal '!P:Q,2,FALSE) -> #N/A
A235: 4784 | B235: 45777 | C235: Apr 2025 | D235: Journal | E235: A/2025/JV/2032 | F235: 13128 Credit Card Dues (MIS) Credit Card Dues (MIS) | G235: Accounts Payable | I235: 23042960 | J235: =_xlfn.CONCAT(A235,F235,G235,I235) -> 478413128 Credit Card Dues (MIS) Credit Card Dues (MIS)Accounts Payable23042959.73 | K235: =VLOOKUP(J235,'April - May Applied Journal '!P:Q,2,FALSE) -> #N/A
A236: 4785 | B236: 45778 | C236: May 2025 | D236: Journal | E236: A/2025/JV/2032 | F236: 13128 Credit Card Dues (MIS) Credit Card Dues (MIS) | G236: Accounts Payable | I236: -23042960 | J236: =_xlfn.CONCAT(A236,F236,G236,I236) -> 478513128 Credit Card Dues (MIS) Credit Card Dues (MIS)Accounts Payable-23042959.73 | K236: =VLOOKUP(J236,'April - May Applied Journal '!P:Q,2,FALSE) -> #N/A
A237: 4811 | B237: 45789 | C237: May 2025 | D237: Journal | E237: A/2025/JV/2143 | F237: 1044808 Sarita Stokes | G237: 1252 LOANS, SECURITY & OTHER RECEIVABLES < 1YEAR : OTHER LOANS & ADVANCES : Advance To Employees | H237: Being On Account to Atish Pawar for SB 20190 EC Expenses Submited to be Sarita Stokes | I237: 8000 | J237: =_xlfn.CONCAT(A237,F237,G237,I237) -> 48111044808 Sarita Stokes1252 LOANS, SECURITY & OTHER RECEIVABLES < 1YEAR : OTHER LOANS & ADVANCES : Advance To Employees8000 | K237: =VLOOKUP(J237,'April - May Applied Journal '!P:Q,2,FALSE) -> #N/A
A238: 4947 | B238: 45794 | C238: May 2025 | D238: Journal | E238: A/2025/JV/2189 | F238: 1136203 Sumit Sangle | G238: 1252 LOANS, SECURITY & OTHER RECEIVABLES < 1YEAR : OTHER LOANS & ADVANCES : Advance To Employees | H238: Being on Account to Sumit Sangle for BU 6 Pravin SB 22691 HUL Dove Scalp Launch Event. | I238: 65000 | J238: =_xlfn.CONCAT(A238,F238,G238,I238) -> 49471136203 Sumit Sangle1252 LOANS, SECURITY & OTHER RECEIVABLES < 1YEAR : OTHER LOANS & ADVANCES : Advance To Employees65000 | K238: =VLOOKUP(J238,'April - May Applied Journal '!P:Q,2,FALSE) -> #N/A
A239: 4948 | B239: 45794 | C239: May 2025 | D239: Journal | E239: A/2025/JV/2190 | F239: 1143165 Karan Nischal | G239: 1252 LOANS, SECURITY & OTHER RECEIVABLES < 1YEAR : OTHER LOANS & ADVANCES : Advance To Employees | H239: Being On Account to Karan Nichal for SB 22561 Dell - Indian Express events in May - 21. | I239: 10000 | J239: =_xlfn.CONCAT(A239,F239,G239,I239) -> 49481143165 Karan Nischal1252 LOANS, SECURITY & OTHER RECEIVABLES < 1YEAR : OTHER LOANS & ADVANCES : Advance To Employees10000 | K239: =VLOOKUP(J239,'April - May Applied Journal '!P:Q,2,FALSE) -> #N/A
A240: 4949 | B240: 45794 | C240: May 2025 | D240: Journal | E240: A/2025/JV/2191 | F240: 1140645 Seemant Mahalwal | G240: 1252 LOANS, SECURITY & OTHER RECEIVABLES < 1YEAR : OTHER LOANS & ADVANCES : Advance To Employees | H240: Being on Account to Seemant Mahalwal for BU 7 A SB 22657 Google YT Shopping Lifestyle edition. | I240: 5000 | J240: =_xlfn.CONCAT(A240,F240,G240,I240) -> 49491140645 Seemant Mahalwal1252 LOANS, SECURITY & OTHER RECEIVABLES < 1YEAR : OTHER LOANS & ADVANCES : Advance To Employees5000 | K240: =VLOOKUP(J240,'April - May Applied Journal '!P:Q,2,FALSE) -> #N/A
A241: 4950 | B241: 45794 | C241: May 2025 | D241: Journal | E241: A/2025/JV/2192 | F241: 1045051 Suresh Pardale | G241: 1252 LOANS, SECURITY & OTHER RECEIVABLES < 1YEAR : OTHER LOANS & ADVANCES : Advance To Employees | H241: Being On Account to Suresh Pardale for SB 20100 General Expenses. | I241: 10000 | J241: =_xlfn.CONCAT(A241,F241,G241,I241) -> 49501045051 Suresh Pardale1252 LOANS, SECURITY & OTHER RECEIVABLES < 1YEAR : OTHER LOANS & ADVANCES : Advance To Employees10000 | K241: =VLOOKUP(J241,'April - May Applied Journal '!P:Q,2,FALSE) -> #N/A
A242: 4951 | B242: 45794 | C242: May 2025 | D242: Journal | E242: A/2025/JV/2193 | F242: 1139551 Kapoor Samarth | G242: 1252 LOANS, SECURITY & OTHER RECEIVABLES < 1YEAR : OTHER LOANS & ADVANCES : Advance To Employees | H242: Being On Account to Samarth Kapoor for BU 7 A SB 22690 Vast Data Swags. | I242: 20000 | J242: =_xlfn.CONCAT(A242,F242,G242,I242) -> 49511139551 Kapoor Samarth1252 LOANS, SECURITY & OTHER RECEIVABLES < 1YEAR : OTHER LOANS & ADVANCES : Advance To Employees20000 | K242: =VLOOKUP(J242,'April - May Applied Journal '!P:Q,2,FALSE) -> #N/A
A243: 4952 | B243: 45794 | C243: May 2025 | D243: Journal | E243: A/2025/JV/2194 | F243: 1139551 Kapoor Samarth | G243: 1252 LOANS, SECURITY & OTHER RECEIVABLES < 1YEAR : OTHER LOANS & ADVANCES : Advance To Employees | H243: Being on Account to Samarth Kapoor for BU 7 A SB 22690 Vast Data Swags. | I243: 5000 | J243: =_xlfn.CONCAT(A243,F243,G243,I243) -> 49521139551 Kapoor Samarth1252 LOANS, SECURITY & OTHER RECEIVABLES < 1YEAR : OTHER LOANS & ADVANCES : Advance To Employees5000 | K243: =VLOOKUP(J243,'April - May Applied Journal '!P:Q,2,FALSE) -> #N/A
A244: 4953 | B244: 45794 | C244: May 2025 | D244: Journal | E244: A/2025/JV/2195 | F244: 1141533 Kunwar Singh Chauhan | G244: 1252 LOANS, SECURITY & OTHER RECEIVABLES < 1YEAR : OTHER LOANS & ADVANCES : Advance To Employees | H244: Being On Account to Kunwar Singh Chauhan for BU 7A SB 22664 Amway BBS Multicity events. | I244: 20500 | J244: =_xlfn.CONCAT(A244,F244,G244,I244) -> 49531141533 Kunwar Singh Chauhan1252 LOANS, SECURITY & OTHER RECEIVABLES < 1YEAR : OTHER LOANS & ADVANCES : Advance To Employees20500 | K244: =VLOOKUP(J244,'April - May Applied Journal '!P:Q,2,FALSE) -> #N/A
...

Sheet April - May Not Applied Journal
A1: Internal ID | B1: Date | C1: Period | D1: Type | E1: Voucher Number | F1: Name | G1: Account | H1: Memo | I1: Amount | J1: Journal Pattern
A2: 3371 | B2: 45748 | C2: Apr 2025 | D2: Journal | E2: A/2025/JV/1525 | F2: 1045050 Padmakar Jadhav | G2: 1252 LOANS, SECURITY & OTHER RECEIVABLES < 1YEAR : OTHER LOANS & ADVANCES : Advance To Employees | I2: 434 | J2: 33711045050 Padmakar Jadhav1252 LOANS, SECURITY & OTHER RECEIVABLES < 1YEAR : OTHER LOANS & ADVANCES : Advance To Employees434 | K2: #N/A
A3: 3376 | B3: 45776 | C3: Apr 2025 | D3: Journal | E3: A/2025/JV/1981 | F3: 1044833 Nazia M | G3: 10340 LOANS, SECURITY & OTHER RECEIVABLES < 1YEAR : LOANS TO EMPLOYEES | I3: -42000 | J3: 33761044833 Nazia M10340 LOANS, SECURITY & OTHER RECEIVABLES < 1YEAR : LOANS TO EMPLOYEES-42000 | K3: #N/A
A4: 3387 | B4: 45776 | C4: Apr 2025 | D4: Journal | E4: A/2025/JV/1985 | F4: 1044945 Pravin Mahajan | G4: 1133 STAFF RELATED LIABILITIES (NO BONUSES) : SALARY & WAGES PAYABLE : Reimbursement | H4: Being Provision for Reimbursement for the month of April 2025 | I4: 32500 | J4: 33871044945 Pravin Mahajan1133 STAFF RELATED LIABILITIES (NO BONUSES) : SALARY & WAGES PAYABLE : Reimbursement32500 | K4: #N/A
A5: 3387 | B5: 45776 | C5: Apr 2025 | D5: Journal | E5: A/2025/JV/1985 | F5: 1044810 Sidhant Saxena | G5: 1133 STAFF RELATED LIABILITIES (NO BONUSES) : SALARY & WAGES PAYABLE : Reimbursement | H5: Being Provision for Reimbursement for the month of April 2025 | I5: 32500 | J5: 33871044810 Sidhant Saxena1133 STAFF RELATED LIABILITIES (NO BONUSES) : SALARY & WAGES PAYABLE : Reimbursement32500 | K5: #N/A
A6: 3387 | B6: 45776 | C6: Apr 2025 | D6: Journal | E6: A/2025/JV/1985 | F6: 1115298 Sony Parikh | G6: 1133 STAFF RELATED LIABILITIES (NO BONUSES) : SALARY & WAGES PAYABLE : Reimbursement | H6: Being Provision for Reimbursement for the month of April 2025 | I6: 30000 | J6: 33871115298 Sony Parikh1133 STAFF RELATED LIABILITIES (NO BONUSES) : SALARY & WAGES PAYABLE : Reimbursement30000 | K6: #N/A
A7: 3387 | B7: 45776 | C7: Apr 2025 | D7: Journal | E7: A/2025/JV/1985 | F7: 1138617 Tejas Damania | G7: 1133 STAFF RELATED LIABILITIES (NO BONUSES) : SALARY & WAGES PAYABLE : Reimbursement | H7: Being Provision for Reimbursement for the month of April 2025 | I7: 24000 | J7: 33871138617 Tejas Damania1133 STAFF RELATED LIABILITIES (NO BONUSES) : SALARY & WAGES PAYABLE : Reimbursement24000 | K7: #N/A
A8: 3390 | B8: 45776 | C8: Apr 2025 | D8: Journal | E8: A/2025/JV/1973 | F8: 1143735 Arun Kumar M | G8: 1252 LOANS, SECURITY & OTHER RECEIVABLES < 1YEAR : OTHER LOANS & ADVANCES : Advance To Employees | H8: Being Advance Account Recoverd from Salary for the month of April 2025 | I8: -5291 | J8: 33901143735 Arun Kumar M1252 LOANS, SECURITY & OTHER RECEIVABLES < 1YEAR : OTHER LOANS & ADVANCES : Advance To Employees-5291 | K8: #N/A
A9: 3390 | B9: 45776 | C9: Apr 2025 | D9: Journal | E9: A/2025/JV/1973 | F9: 1119879 Kapeel Parmekar | G9: 1252 LOANS, SECURITY & OTHER RECEIVABLES < 1YEAR : OTHER LOANS & ADVANCES : Advance To Employees | H9: Being Advance Account Recoverd from Salary for the month of April 2025 | I9: -13398.56 | J9: 33901119879 Kapeel Parmekar1252 LOANS, SECURITY & OTHER RECEIVABLES < 1YEAR : OTHER LOANS & ADVANCES : Advance To Employees-13398.56 | K9: #N/A
A10: 3390 | B10: 45776 | C10: Apr 2025 | D10: Journal | E10: A/2025/JV/1973 | F10: 1144574 Mahesh D | G10: 1252 LOANS, SECURITY & OTHER RECEIVABLES < 1YEAR : OTHER LOANS & ADVANCES : Advance To Employees | H10: Being Advance Account Recoverd from Salary for the month of April 2025 | I10: -1852 | J10: 33901144574 Mahesh D1252 LOANS, SECURITY & OTHER RECEIVABLES < 1YEAR : OTHER LOANS & ADVANCES : Advance To Employees-1852 | K10: #N/A
A11: 3404 | B11: 45748 | C11: Apr 2025 | D11: Journal | E11: A/2025/JV/1534 | F11: 1044950 Santosh Singh | G11: 1252 LOANS, SECURITY & OTHER RECEIVABLES < 1YEAR : OTHER LOANS & ADVANCES : Advance To Employees | H11: Being on Account to Santosh Singh for SB 22540 SAP Now 2025 | I11: 25000 | J11: 34041044950 Santosh Singh1252 LOANS, SECURITY & OTHER RECEIVABLES < 1YEAR : OTHER LOANS & ADVANCES : Advance To Employees25000 | K11: #N/A
A12: 3458 | B12: 45748 | C12: Apr 2025 | D12: Journal | E12: A/2025/JV/1535 | F12: 1126217 Ritu Vohra | G12: 1252 LOANS, SECURITY & OTHER RECEIVABLES < 1YEAR : OTHER LOANS & ADVANCES : Advance To Employees | H12: Being on Account to Ritu Vohra for BU 7 SB 15860 Meeting | I12: 17000 | J12: 34581126217 Ritu Vohra1252 LOANS, SECURITY & OTHER RECEIVABLES < 1YEAR : OTHER LOANS & ADVANCES : Advance To Employees17000 | K12: #N/A
A13: 3459 | B13: 45748 | C13: Apr 2025 | D13: Journal | E13: A/2025/JV/1536 | F13: 1133840 Srinivasa Dasari | G13: 1252 LOANS, SECURITY & OTHER RECEIVABLES < 1YEAR : OTHER LOANS & ADVANCES : Advance To Employees | H13: Being on Account to Srinivasa Dasari for BU 9 Bangalore SB 22565 Apparel Fashion Tech World on 04.04.2025 | I13: 13530 | J13: 34591133840 Srinivasa Dasari1252 LOANS, SECURITY & OTHER RECEIVABLES < 1YEAR : OTHER LOANS & ADVANCES : Advance To Employees13530 | K13: #N/A
A14: 3460 | B14: 45748 | C14: Apr 2025 | D14: Journal | E14: A/2025/JV/1537 | F14: 1044966 Harshit Jain | G14: 1252 LOANS, SECURITY & OTHER RECEIVABLES < 1YEAR : OTHER LOANS & ADVANCES : Advance To Employees | H14: Being on Account to Harshit Jain for SB 22344 BU 7 A Github Galaxy 2025 | I14: 100000 | J14: 34601044966 Harshit Jain1252 LOANS, SECURITY & OTHER RECEIVABLES < 1YEAR : OTHER LOANS & ADVANCES : Advance To Employees100000 | K14: #N/A
A15: 3461 | B15: 45748 | C15: Apr 2025 | D15: Journal | E15: A/2025/JV/1538 | F15: 1044826 Hazarat Ansari | G15: 1252 LOANS, SECURITY & OTHER RECEIVABLES < 1YEAR : OTHER LOANS & ADVANCES : Advance To Employees | H15: Being On Account to Hazarat Ansari for BU 1 Rajesh SB 22511 Accenture Interns Welcome Networking Dinner. | I15: 10000 | J15: 34611044826 Hazarat Ansari1252 LOANS, SECURITY & OTHER RECEIVABLES < 1YEAR : OTHER LOANS & ADVANCES : Advance To Employees10000 | K15: #N/A
... A215: 4696 | B215: 45764 | C215: Apr 2025 | D215: Journal | E215: A/2025/JV/1730 | F215: 1044827 Abdul Rahman | G215: 1252 LOANS, SECURITY & OTHER RECEIVABLES < 1YEAR : OTHER LOANS & ADVANCES : Advance To Employees | H215: Being On Account to Abdul Rehman for SB 22559 HPE Cloud Connect. | I215: 10000 | J215: 46961044827 Abdul Rahman1252 LOANS, SECURITY & OTHER RECEIVABLES < 1YEAR : OTHER LOANS & ADVANCES : Advance To Employees10000 | K215: #N/A
A216: 4697 | B216: 45748 | C216: Apr 2025 | D216: Journal | E216: A/2025/JV/1515/Rev | F216: 13128 Credit Card Dues (MIS) Credit Card Dues (MIS) | G216: Accounts Payable | I216: -26496206 | J216: 469713128 Credit Card Dues (MIS) Credit Card Dues (MIS)Accounts Payable-26496206.39 | K216: #N/A
